Workbook

Sheet Guide
B1: How to use this file / วิธีใช้ไฟล์นี้
B3: Three tabs | C3: Dashboard = the overview. Register = where you type. Lists = the dropdown choices.
B4: แท็บ 3 อัน | C4: Dashboard คือภาพรวม, Register คือที่กรอกข้อมูล, Lists คือรายการตัวเลือก
B6: Step 1 | C6: Go to the Register tab. Each row is one licence, permit, tax, insurance policy or contract.
B7: Step 2 | C7: Fill in: Reference / Licence no., Issue date, Expiry date, Responsible person, Fee, and where the document is kept.
B9: Renew by | C9: The important split: OWNER or PROPERTY — who has to renew it. Pick from the dropdown. Owner rows are blue, Property rows are purple, and the Dashboard shows the two as two separate tables.
B10: Renew by = Owner | C10: The asset company (AMH … Co., Ltd.): the building and its inspections, the company registrations and taxes, asset insurance, the management agreement, lease and bank facilities.
B11: Renew by = Property | C11: The hotel operation: guest-facing licences (food, alcohol, pool), staff permits and health certificates, OTA agreements, and operating suppliers such as laundry, security, cleaning.
B12: ผู้ต่ออายุ | C12: Owner = เจ้าของอาคาร (บริษัท AMH) ดูแลตัวอาคาร ทะเบียนบริษัท ภาษี ประกันทรัพย์สิน สัญญาหลัก / Property = ฝ่ายโรงแรม ดูแลใบอนุญาตหน้างาน พนักงาน OTA และซัพพลายเออร์
B13: See one side only | C13: On the Register click the filter arrow on 'Renew by' and tick just Owner or just Property.
B14: Step 3 | C14: Leave the grey formula columns alone — Action by, Days left and Status fill themselves in.
B15: Step 4 | C15: Open the Dashboard tab to see what is expiring.
B17: The Dashboard | C17: Owner first, then Property. Each one is counted twice — once BY HOTEL and once BY DOCUMENT TYPE (licence, permit, certificate, tax, insurance, contract) — so a red number tells you which hotel and what kind of document.
... B34: Rebuild | C34: scripts/build_license_tracker.py rebuilds this file's structure. Rebuilding starts from empty rows, so keep your filled-in copy — do not overwrite it.

Sheet Dashboard
A1: Licence & Contract Dashboard — 4 properties
A2: Split by who renews it (OWNER / PROPERTY), then by hotel and by document type. All of it reads the Register tab. แยกตามผู้รับผิดชอบ แล้วแยกตามโรงแรมและประเภทเอกสาร
A4: As at | B4: =TODAY()
A6: OWNER — renewed by the asset company (AMH …) / เจ้าของอาคาร
A7: Hotel | B7: Expired | C7: Urgent (≤30 d) | D7: Due soon (≤90 d) | E7: OK | F7: No date | G7: Total
A8: SR9 | B8: =COUNTIFS(Register!$B$5:$B$404,"SR9",Register!$E$5:$E$404,"Owner",Register!$P$5:$P$404,"Expired") | C8: =COUNTIFS(Register!$B$5:$B$404,"SR9",Register!$E$5:$E$404,"Owner",Register!$P$5:$P$404,"Urgent") | D8: =COUNTIFS(Register!$B$5:$B$404,"SR9",Register!$E$5:$E$404,"Owner",Register!$P$5:$P$404,"Due soon") | E8: =COUNTIFS(Register!$B$5:$B$404,"SR9",Register!$E$5:$E$404,"Owner",Register!$P$5:$P$404,"OK") | F8: =COUNTIFS(Register!$B$5:$B$404,"SR9",Register!$E$5:$E$404,"Owner",Register!$P$5:$P$404,"No date") | G8: =COUNTIFS(Register!$B$5:$B$404,"SR9",Register!$E$5:$E$404,"Owner",Register!$F$5:$F$404,"?*") | I8: Somerset Rama 9 Bangkok
A9: AES | B9: =COUNTIFS(Register!$B$5:$B$404,"AES",Register!$E$5:$E$404,"Owner",Register!$P$5:$P$404,"Expired") | C9: =COUNTIFS(Register!$B$5:$B$404,"AES",Register!$E$5:$E$404,"Owner",Register!$P$5:$P$404,"Urgent") | D9: =COUNTIFS(Register!$B$5:$B$404,"AES",Register!$E$5:$E$404,"Owner",Register!$P$5:$P$404,"Due soon") | E9: =COUNTIFS(Register!$B$5:$B$404,"AES",Register!$E$5:$E$404,"Owner",Register!$P$5:$P$404,"OK") | F9: =COUNTIFS(Register!$B$5:$B$404,"AES",Register!$E$5:$E$404,"Owner",Register!$P$5:$P$404,"No date") | G9: =COUNTIFS(Register!$B$5:$B$404,"AES",Register!$E$5:$E$404,"Owner",Register!$F$5:$F$404,"?*") | I9: Ascott Embassy Sathorn Bangkok
A10: LYF | B10: =COUNTIFS(Register!$B$5:$B$404,"LYF",Register!$E$5:$E$404,"Owner",Register!$P$5:$P$404,"Expired") | C10: =COUNTIFS(Register!$B$5:$B$404,"LYF",Register!$E$5:$E$404,"Owner",Register!$P$5:$P$404,"Urgent") | D10: =COUNTIFS(Register!$B$5:$B$404,"LYF",Register!$E$5:$E$404,"Owner",Register!$P$5:$P$404,"Due soon") | E10: =COUNTIFS(Register!$B$5:$B$404,"LYF",Register!$E$5:$E$404,"Owner",Register!$P$5:$P$404,"OK") | F10: =COUNTIFS(Register!$B$5:$B$404,"LYF",Register!$E$5:$E$404,"Owner",Register!$P$5:$P$404,"No date") | G10: =COUNTIFS(Register!$B$5:$B$404,"LYF",Register!$E$5:$E$404,"Owner",Register!$F$5:$F$404,"?*") | I10: lyf Sukhumvit 8 Bangkok
A11: SP | B11: =COUNTIFS(Register!$B$5:$B$404,"SP",Register!$E$5:$E$404,"Owner",Register!$P$5:$P$404,"Expired") | C11: =COUNTIFS(Register!$B$5:$B$404,"SP",Register!$E$5:$E$404,"Owner",Register!$P$5:$P$404,"Urgent") | D11: =COUNTIFS(Register!$B$5:$B$404,"SP",Register!$E$5:$E$404,"Owner",Register!$P$5:$P$404,"Due soon") | E11: =COUNTIFS(Register!$B$5:$B$404,"SP",Register!$E$5:$E$404,"Owner",Register!$P$5:$P$404,"OK") | F11: =COUNTIFS(Register!$B$5:$B$404,"SP",Register!$E$5:$E$404,"Owner",Register!$P$5:$P$404,"No date") | G11: =COUNTIFS(Register!$B$5:$B$404,"SP",Register!$E$5:$E$404,"Owner",Register!$F$5:$F$404,"?*") | I11: Somerset Pattaya
A12: Subtotal | B12: =SUM(B8:B11) | C12: =SUM(C8:C11) | D12: =SUM(D8:D11) | E12: =SUM(E8:E11) | F12: =SUM(F8:F11) | G12: =SUM(G8:G11)
A14: Document type | B14: Expired | C14: Urgent (≤30 d) | D14: Due soon (≤90 d) | E14: OK | F14: No date | G14: Total
A15: Licence | B15: =COUNTIFS(Register!$D$5:$D$404,"Licence",Register!$E$5:$E$404,"Owner",Register!$P$5:$P$404,"Expired") | C15: =COUNTIFS(Register!$D$5:$D$404,"Licence",Register!$E$5:$E$404,"Owner",Register!$P$5:$P$404,"Urgent") | D15: =COUNTIFS(Register!$D$5:$D$404,"Licence",Register!$E$5:$E$404,"Owner",Register!$P$5:$P$404,"Due soon") | E15: =COUNTIFS(Register!$D$5:$D$404,"Licence",Register!$E$5:$E$404,"Owner",Register!$P$5:$P$404,"OK") | F15: =COUNTIFS(Register!$D$5:$D$404,"Licence",Register!$E$5:$E$404,"Owner",Register!$P$5:$P$404,"No date") | G15: =COUNTIFS(Register!$D$5:$D$404,"Licence",Register!$E$5:$E$404,"Owner",Register!$F$5:$F$404,"?*")
A16: Permit | B16: =COUNTIFS(Register!$D$5:$D$404,"Permit",Register!$E$5:$E$404,"Owner",Register!$P$5:$P$404,"Expired") | C16: =COUNTIFS(Register!$D$5:$D$404,"Permit",Register!$E$5:$E$404,"Owner",Register!$P$5:$P$404,"Urgent") | D16: =COUNTIFS(Register!$D$5:$D$404,"Permit",Register!$E$5:$E$404,"Owner",Register!$P$5:$P$404,"Due soon") | E16: =COUNTIFS(Register!$D$5:$D$404,"Permit",Register!$E$5:$E$404,"Owner",Register!$P$5:$P$404,"OK") | F16: =COUNTIFS(Register!$D$5:$D$404,"Permit",Register!$E$5:$E$404,"Owner",Register!$P$5:$P$404,"No date") | G16: =COUNTIFS(Register!$D$5:$D$404,"Permit",Register!$E$5:$E$404,"Owner",Register!$F$5:$F$404,"?*")
A17: Certificate | B17: =COUNTIFS(Register!$D$5:$D$404,"Certificate",Register!$E$5:$E$404,"Owner",Register!$P$5:$P$404,"Expired") | C17: =COUNTIFS(Register!$D$5:$D$404,"Certificate",Register!$E$5:$E$404,"Owner",Register!$P$5:$P$404,"Urgent") | D17: =COUNTIFS(Register!$D$5:$D$404,"Certificate",Register!$E$5:$E$404,"Owner",Register!$P$5:$P$404,"Due soon") | E17: =COUNTIFS(Register!$D$5:$D$404,"Certificate",Register!$E$5:$E$404,"Owner",Register!$P$5:$P$404,"OK") | F17: =COUNTIFS(Register!$D$5:$D$404,"Certificate",Register!$E$5:$E$404,"Owner",Register!$P$5:$P$404,"No date") | G17: =COUNTIFS(Register!$D$5:$D$404,"Certificate",Register!$E$5:$E$404,"Owner",Register!$F$5:$F$404,"?*")
A18: Tax / Registration | B18: =COUNTIFS(Register!$D$5:$D$404,"Tax / Registration",Register!$E$5:$E$404,"Owner",Register!$P$5:$P$404,"Expired") | C18: =COUNTIFS(Register!$D$5:$D$404,"Tax / Registration",Register!$E$5:$E$404,"Owner",Register!$P$5:$P$404,"Urgent") | D18: =COUNTIFS(Register!$D$5:$D$404,"Tax / Registration",Register!$E$5:$E$404,"Owner",Register!$P$5:$P$404,"Due soon") | E18: =COUNTIFS(Register!$D$5:$D$404,"Tax / Registration",Register!$E$5:$E$404,"Owner",Register!$P$5:$P$404,"OK") | F18: =COUNTIFS(Register!$D$5:$D$404,"Tax / Registration",Register!$E$5:$E$404,"Owner",Register!$P$5:$P$404,"No date") | G18: =COUNTIFS(Register!$D$5:$D$404,"Tax / Registration",Register!$E$5:$E$404,"Owner",Register!$F$5:$F$404,"?*")
A19: Insurance | B19: =COUNTIFS(Register!$D$5:$D$404,"Insurance",Register!$E$5:$E$404,"Owner",Register!$P$5:$P$404,"Expired") | C19: =COUNTIFS(Register!$D$5:$D$404,"Insurance",Register!$E$5:$E$404,"Owner",Register!$P$5:$P$404,"Urgent") | D19: =COUNTIFS(Register!$D$5:$D$404,"Insurance",Register!$E$5:$E$404,"Owner",Register!$P$5:$P$404,"Due soon") | E19: =COUNTIFS(Register!$D$5:$D$404,"Insurance",Register!$E$5:$E$404,"Owner",Register!$P$5:$P$404,"OK") | F19: =COUNTIFS(Register!$D$5:$D$404,"Insurance",Register!$E$5:$E$404,"Owner",Register!$P$5:$P$404,"No date") | G19: =COUNTIFS(Register!$D$5:$D$404,"Insurance",Register!$E$5:$E$404,"Owner",Register!$F$5:$F$404,"?*")
A20: Contract - Management | B20: =COUNTIFS(Register!$D$5:$D$404,"Contract - Management",Register!$E$5:$E$404,"Owner",Register!$P$5:$P$404,"Expired") | C20: =COUNTIFS(Register!$D$5:$D$404,"Contract - Management",Register!$E$5:$E$404,"Owner",Register!$P$5:$P$404,"Urgent") | D20: =COUNTIFS(Register!$D$5:$D$404,"Contract - Management",Register!$E$5:$E$404,"Owner",Register!$P$5:$P$404,"Due soon") | E20: =COUNTIFS(Register!$D$5:$D$404,"Contract - Management",Register!$E$5:$E$404,"Owner",Register!$P$5:$P$404,"OK") | F20: =COUNTIFS(Register!$D$5:$D$404,"Contract - Management",Register!$E$5:$E$404,"Owner",Register!$P$5:$P$404,"No date") | G20: =COUNTIFS(Register!$D$5:$D$404,"Contract - Management",Register!$E$5:$E$404,"Owner",Register!$F$5:$F$404,"?*")
A21: Contract - OTA | B21: =COUNTIFS(Register!$D$5:$D$404,"Contract - OTA",Register!$E$5:$E$404,"Owner",Register!$P$5:$P$404,"Expired") | C21: =COUNTIFS(Register!$D$5:$D$404,"Contract - OTA",Register!$E$5:$E$404,"Owner",Register!$P$5:$P$404,"Urgent") | D21: =COUNTIFS(Register!$D$5:$D$404,"Contract - OTA",Register!$E$5:$E$404,"Owner",Register!$P$5:$P$404,"Due soon") | E21: =COUNTIFS(Register!$D$5:$D$404,"Contract - OTA",Register!$E$5:$E$404,"Owner",Register!$P$5:$P$404,"OK") | F21: =COUNTIFS(Register!$D$5:$D$404,"Contract - OTA",Register!$E$5:$E$404,"Owner",Register!$P$5:$P$404,"No date") | G21: =COUNTIFS(Register!$D$5:$D$404,"Contract - OTA",Register!$E$5:$E$404,"Owner",Register!$F$5:$F$404,"?*")
A22: Contract - Service | B22: =COUNTIFS(Register!$D$5:$D$404,"Contract - Service",Register!$E$5:$E$404,"Owner",Register!$P$5:$P$404,"Expired") | C22: =COUNTIFS(Register!$D$5:$D$404,"Contract - Service",Register!$E$5:$E$404,"Owner",Register!$P$5:$P$404,"Urgent") | D22: =COUNTIFS(Register!$D$5:$D$404,"Contract - Service",Register!$E$5:$E$404,"Owner",Register!$P$5:$P$404,"Due soon") | E22: =COUNTIFS(Register!$D$5:$D$404,"Contract - Service",Register!$E$5:$E$404,"Owner",Register!$P$5:$P$404,"OK") | F22: =COUNTIFS(Register!$D$5:$D$404,"Contract - Service",Register!$E$5:$E$404,"Owner",Register!$P$5:$P$404,"No date") | G22: =COUNTIFS(Register!$D$5:$D$404,"Contract - Service",Register!$E$5:$E$404,"Owner",Register!$F$5:$F$404,"?*")
A23: Contract - Utility | B23: =COUNTIFS(Register!$D$5:$D$404,"Contract - Utility",Register!$E$5:$E$404,"Owner",Register!$P$5:$P$404,"Expired") | C23: =COUNTIFS(Register!$D$5:$D$404,"Contract - Utility",Register!$E$5:$E$404,"Owner",Register!$P$5:$P$404,"Urgent") | D23: =COUNTIFS(Register!$D$5:$D$404,"Contract - Utility",Register!$E$5:$E$404,"Owner",Register!$P$5:$P$404,"Due soon") | E23: =COUNTIFS(Register!$D$5:$D$404,"Contract - Utility",Register!$E$5:$E$404,"Owner",Register!$P$5:$P$404,"OK") | F23: =COUNTIFS(Register!$D$5:$D$404,"Contract - Utility",Register!$E$5:$E$404,"Owner",Register!$P$5:$P$404,"No date") | G23: =COUNTIFS(Register!$D$5:$D$404,"Contract - Utility",Register!$E$5:$E$404,"Owner",Register!$F$5:$F$404,"?*")
A24: Contract - Lease / Finance | B24: =COUNTIFS(Register!$D$5:$D$404,"Contract - Lease / Finance",Register!$E$5:$E$404,"Owner",Register!$P$5:$P$404,"Expired") | C24: =COUNTIFS(Register!$D$5:$D$404,"Contract - Lease / Finance",Register!$E$5:$E$404,"Owner",Register!$P$5:$P$404,"Urgent") | D24: =COUNTIFS(Register!$D$5:$D$404,"Contract - Lease / Finance",Register!$E$5:$E$404,"Owner",Register!$P$5:$P$404,"Due soon") | E24: =COUNTIFS(Register!$D$5:$D$404,"Contract - Lease / Finance",Register!$E$5:$E$404,"Owner",Register!$P$5:$P$404,"OK") | F24: =COUNTIFS(Register!$D$5:$D$404,"Contract - Lease / Finance",Register!$E$5:$E$404,"Owner",Register!$P$5:$P$404,"No date") | G24: =COUNTIFS(Register!$D$5:$D$404,"Contract - Lease / Finance",Register!$E$5:$E$404,"Owner",Register!$F$5:$F$404,"?*")
A25: Subtotal | B25: =SUM(B15:B24) | C25: =SUM(C15:C24) | D25: =SUM(D15:D24) | E25: =SUM(E15:E24) | F25: =SUM(F15:F24) | G25: =SUM(G15:G24) | I25: =IF(G25=G12,"✓ same total as by hotel","CHECK — does not match by hotel")
A27: PROPERTY — renewed by the hotel operation / ฝ่ายโรงแรม
A28: Hotel | B28: Expired | C28: Urgent (≤30 d) | D28: Due soon (≤90 d) | E28: OK | F28: No date | G28: Total
A29: SR9 | B29: =COUNTIFS(Register!$B$5:$B$404,"SR9",Register!$E$5:$E$404,"Property",Register!$P$5:$P$404,"Expired") | C29: =COUNTIFS(Register!$B$5:$B$404,"SR9",Register!$E$5:$E$404,"Property",Register!$P$5:$P$404,"Urgent") | D29: =COUNTIFS(Register!$B$5:$B$404,"SR9",Register!$E$5:$E$404,"Property",Register!$P$5:$P$404,"Due soon") | E29: =COUNTIFS(Register!$B$5:$B$404,"SR9",Register!$E$5:$E$404,"Property",Register!$P$5:$P$404,"OK") | F29: =COUNTIFS(Register!$B$5:$B$404,"SR9",Register!$E$5:$E$404,"Property",Register!$P$5:$P$404,"No date") | G29: =COUNTIFS(Register!$B$5:$B$404,"SR9",Register!$E$5:$E$404,"Property",Register!$F$5:$F$404,"?*") | I29: Somerset Rama 9 Bangkok
A30: AES | B30: =COUNTIFS(Register!$B$5:$B$404,"AES",Register!$E$5:$E$404,"Property",Register!$P$5:$P$404,"Expired") | C30: =COUNTIFS(Register!$B$5:$B$404,"AES",Register!$E$5:$E$404,"Property",Register!$P$5:$P$404,"Urgent") | D30: =COUNTIFS(Register!$B$5:$B$404,"AES",Register!$E$5:$E$404,"Property",Register!$P$5:$P$404,"Due soon") | E30: =COUNTIFS(Register!$B$5:$B$404,"AES",Register!$E$5:$E$404,"Property",Register!$P$5:$P$404,"OK") | F30: =COUNTIFS(Register!$B$5:$B$404,"AES",Register!$E$5:$E$404,"Property",Register!$P$5:$P$404,"No date") | G30: =COUNTIFS(Register!$B$5:$B$404,"AES",Register!$E$5:$E$404,"Property",Register!$F$5:$F$404,"?*") | I30: Ascott Embassy Sathorn Bangkok
A31: LYF | B31: =COUNTIFS(Register!$B$5:$B$404,"LYF",Register!$E$5:$E$404,"Property",Register!$P$5:$P$404,"Expired") | C31: =COUNTIFS(Register!$B$5:$B$404,"LYF",Register!$E$5:$E$404,"Property",Register!$P$5:$P$404,"Urgent") | D31: =COUNTIFS(Register!$B$5:$B$404,"LYF",Register!$E$5:$E$404,"Property",Register!$P$5:$P$404,"Due soon") | E31: =COUNTIFS(Register!$B$5:$B$404,"LYF",Register!$E$5:$E$404,"Property",Register!$P$5:$P$404,"OK") | F31: =COUNTIFS(Register!$B$5:$B$404,"LYF",Register!$E$5:$E$404,"Property",Register!$P$5:$P$404,"No date") | G31: =COUNTIFS(Register!$B$5:$B$404,"LYF",Register!$E$5:$E$404,"Property",Register!$F$5:$F$404,"?*") | I31: lyf Sukhumvit 8 Bangkok
A32: SP | B32: =COUNTIFS(Register!$B$5:$B$404,"SP",Register!$E$5:$E$404,"Property",Register!$P$5:$P$404,"Expired") | C32: =COUNTIFS(Register!$B$5:$B$404,"SP",Register!$E$5:$E$404,"Property",Register!$P$5:$P$404,"Urgent") | D32: =COUNTIFS(Register!$B$5:$B$404,"SP",Register!$E$5:$E$404,"Property",Register!$P$5:$P$404,"Due soon") | E32: =COUNTIFS(Register!$B$5:$B$404,"SP",Register!$E$5:$E$404,"Property",Register!$P$5:$P$404,"OK") | F32: =COUNTIFS(Register!$B$5:$B$404,"SP",Register!$E$5:$E$404,"Property",Register!$P$5:$P$404,"No date") | G32: =COUNTIFS(Register!$B$5:$B$404,"SP",Register!$E$5:$E$404,"Property",Register!$F$5:$F$404,"?*") | I32: Somerset Pattaya
A33: Subtotal | B33: =SUM(B29:B32) | C33: =SUM(C29:C32) | D33: =SUM(D29:D32) | E33: =SUM(E29:E32) | F33: =SUM(F29:F32) | G33: =SUM(G29:G32)
A35: Document type | B35: Expired | C35: Urgent (≤30 d) | D35: Due soon (≤90 d) | E35: OK | F35: No date | G35: Total
A36: Licence | B36: =COUNTIFS(Register!$D$5:$D$404,"Licence",Register!$E$5:$E$404,"Property",Register!$P$5:$P$404,"Expired") | C36: =COUNTIFS(Register!$D$5:$D$404,"Licence",Register!$E$5:$E$404,"Property",Register!$P$5:$P$404,"Urgent") | D36: =COUNTIFS(Register!$D$5:$D$404,"Licence",Register!$E$5:$E$404,"Property",Register!$P$5:$P$404,"Due soon") | E36: =COUNTIFS(Register!$D$5:$D$404,"Licence",Register!$E$5:$E$404,"Property",Register!$P$5:$P$404,"OK") | F36: =COUNTIFS(Register!$D$5:$D$404,"Licence",Register!$E$5:$E$404,"Property",Register!$P$5:$P$404,"No date") | G36: =COUNTIFS(Register!$D$5:$D$404,"Licence",Register!$E$5:$E$404,"Property",Register!$F$5:$F$404,"?*")
A37: Permit | B37: =COUNTIFS(Register!$D$5:$D$404,"Permit",Register!$E$5:$E$404,"Property",Register!$P$5:$P$404,"Expired") | C37: =COUNTIFS(Register!$D$5:$D$404,"Permit",Register!$E$5:$E$404,"Property",Register!$P$5:$P$404,"Urgent") | D37: =COUNTIFS(Register!$D$5:$D$404,"Permit",Register!$E$5:$E$404,"Property",Register!$P$5:$P$404,"Due soon") | E37: =COUNTIFS(Register!$D$5:$D$404,"Permit",Register!$E$5:$E$404,"Property",Register!$P$5:$P$404,"OK") | F37: =COUNTIFS(Register!$D$5:$D$404,"Permit",Register!$E$5:$E$404,"Property",Register!$P$5:$P$404,"No date") | G37: =COUNTIFS(Register!$D$5:$D$404,"Permit",Register!$E$5:$E$404,"Property",Register!$F$5:$F$404,"?*")
A38: Certificate | B38: =COUNTIFS(Register!$D$5:$D$404,"Certificate",Register!$E$5:$E$404,"Property",Register!$P$5:$P$404,"Expired") | C38: =COUNTIFS(Register!$D$5:$D$404,"Certificate",Register!$E$5:$E$404,"Property",Register!$P$5:$P$404,"Urgent") | D38: =COUNTIFS(Register!$D$5:$D$404,"Certificate",Register!$E$5:$E$404,"Property",Register!$P$5:$P$404,"Due soon") | E38: =COUNTIFS(Register!$D$5:$D$404,"Certificate",Register!$E$5:$E$404,"Property",Register!$P$5:$P$404,"OK") | F38: =COUNTIFS(Register!$D$5:$D$404,"Certificate",Register!$E$5:$E$404,"Property",Register!$P$5:$P$404,"No date") | G38: =COUNTIFS(Register!$D$5:$D$404,"Certificate",Register!$E$5:$E$404,"Property",Register!$F$5:$F$404,"?*")
A39: Tax / Registration | B39: =COUNTIFS(Register!$D$5:$D$404,"Tax / Registration",Register!$E$5:$E$404,"Property",Register!$P$5:$P$404,"Expired") | C39: =COUNTIFS(Register!$D$5:$D$404,"Tax / Registration",Register!$E$5:$E$404,"Property",Register!$P$5:$P$404,"Urgent") | D39: =COUNTIFS(Register!$D$5:$D$404,"Tax / Registration",Register!$E$5:$E$404,"Property",Register!$P$5:$P$404,"Due soon") | E39: =COUNTIFS(Register!$D$5:$D$404,"Tax / Registration",Register!$E$5:$E$404,"Property",Register!$P$5:$P$404,"OK") | F39: =COUNTIFS(Register!$D$5:$D$404,"Tax / Registration",Register!$E$5:$E$404,"Property",Register!$P$5:$P$404,"No date") | G39: =COUNTIFS(Register!$D$5:$D$404,"Tax / Registration",Register!$E$5:$E$404,"Property",Register!$F$5:$F$404,"?*")
A40: Insurance | B40: =COUNTIFS(Register!$D$5:$D$404,"Insurance",Register!$E$5:$E$404,"Property",Register!$P$5:$P$404,"Expired") | C40: =COUNTIFS(Register!$D$5:$D$404,"Insurance",Register!$E$5:$E$404,"Property",Register!$P$5:$P$404,"Urgent") | D40: =COUNTIFS(Register!$D$5:$D$404,"Insurance",Register!$E$5:$E$404,"Property",Register!$P$5:$P$404,"Due soon") | E40: =COUNTIFS(Register!$D$5:$D$404,"Insurance",Register!$E$5:$E$404,"Property",Register!$P$5:$P$404,"OK") | F40: =COUNTIFS(Register!$D$5:$D$404,"Insurance",Register!$E$5:$E$404,"Property",Register!$P$5:$P$404,"No date") | G40: =COUNTIFS(Register!$D$5:$D$404,"Insurance",Register!$E$5:$E$404,"Property",Register!$F$5:$F$404,"?*")
A41: Contract - Management | B41: =COUNTIFS(Register!$D$5:$D$404,"Contract - Management",Register!$E$5:$E$404,"Property",Register!$P$5:$P$404,"Expired") | C41: =COUNTIFS(Register!$D$5:$D$404,"Contract - Management",Register!$E$5:$E$404,"Property",Register!$P$5:$P$404,"Urgent") | D41: =COUNTIFS(Register!$D$5:$D$404,"Contract - Management",Register!$E$5:$E$404,"Property",Register!$P$5:$P$404,"Due soon") | E41: =COUNTIFS(Register!$D$5:$D$404,"Contract - Management",Register!$E$5:$E$404,"Property",Register!$P$5:$P$404,"OK") | F41: =COUNTIFS(Register!$D$5:$D$404,"Contract - Management",Register!$E$5:$E$404,"Property",Register!$P$5:$P$404,"No date") | G41: =COUNTIFS(Register!$D$5:$D$404,"Contract - Management",Register!$E$5:$E$404,"Property",Register!$F$5:$F$404,"?*")
A42: Contract - OTA | B42: =COUNTIFS(Register!$D$5:$D$404,"Contract - OTA",Register!$E$5:$E$404,"Property",Register!$P$5:$P$404,"Expired") | C42: =COUNTIFS(Register!$D$5:$D$404,"Contract - OTA",Register!$E$5:$E$404,"Property",Register!$P$5:$P$404,"Urgent") | D42: =COUNTIFS(Register!$D$5:$D$404,"Contract - OTA",Register!$E$5:$E$404,"Property",Register!$P$5:$P$404,"Due soon") | E42: =COUNTIFS(Register!$D$5:$D$404,"Contract - OTA",Register!$E$5:$E$404,"Property",Register!$P$5:$P$404,"OK") | F42: =COUNTIFS(Register!$D$5:$D$404,"Contract - OTA",Register!$E$5:$E$404,"Property",Register!$P$5:$P$404,"No date") | G42: =COUNTIFS(Register!$D$5:$D$404,"Contract - OTA",Register!$E$5:$E$404,"Property",Register!$F$5:$F$404,"?*")
A43: Contract - Service | B43: =COUNTIFS(Register!$D$5:$D$404,"Contract - Service",Register!$E$5:$E$404,"Property",Register!$P$5:$P$404,"Expired") | C43: =COUNTIFS(Register!$D$5:$D$404,"Contract - Service",Register!$E$5:$E$404,"Property",Register!$P$5:$P$404,"Urgent") | D43: =COUNTIFS(Register!$D$5:$D$404,"Contract - Service",Register!$E$5:$E$404,"Property",Register!$P$5:$P$404,"Due soon") | E43: =COUNTIFS(Register!$D$5:$D$404,"Contract - Service",Register!$E$5:$E$404,"Property",Register!$P$5:$P$404,"OK") | F43: =COUNTIFS(Register!$D$5:$D$404,"Contract - Service",Register!$E$5:$E$404,"Property",Register!$P$5:$P$404,"No date") | G43: =COUNTIFS(Register!$D$5:$D$404,"Contract - Service",Register!$E$5:$E$404,"Property",Register!$F$5:$F$404,"?*")
A44: Contract - Utility | B44: =COUNTIFS(Register!$D$5:$D$404,"Contract - Utility",Register!$E$5:$E$404,"Property",Register!$P$5:$P$404,"Expired") | C44: =COUNTIFS(Register!$D$5:$D$404,"Contract - Utility",Register!$E$5:$E$404,"Property",Register!$P$5:$P$404,"Urgent") | D44: =COUNTIFS(Register!$D$5:$D$404,"Contract - Utility",Register!$E$5:$E$404,"Property",Register!$P$5:$P$404,"Due soon") | E44: =COUNTIFS(Register!$D$5:$D$404,"Contract - Utility",Register!$E$5:$E$404,"Property",Register!$P$5:$P$404,"OK") | F44: =COUNTIFS(Register!$D$5:$D$404,"Contract - Utility",Register!$E$5:$E$404,"Property",Register!$P$5:$P$404,"No date") | G44: =COUNTIFS(Register!$D$5:$D$404,"Contract - Utility",Register!$E$5:$E$404,"Property",Register!$F$5:$F$404,"?*")
A45: Contract - Lease / Finance | B45: =COUNTIFS(Register!$D$5:$D$404,"Contract - Lease / Finance",Register!$E$5:$E$404,"Property",Register!$P$5:$P$404,"Expired") | C45: =COUNTIFS(Register!$D$5:$D$404,"Contract - Lease / Finance",Register!$E$5:$E$404,"Property",Register!$P$5:$P$404,"Urgent") | D45: =COUNTIFS(Register!$D$5:$D$404,"Contract - Lease / Finance",Register!$E$5:$E$404,"Property",Register!$P$5:$P$404,"Due soon") | E45: =COUNTIFS(Register!$D$5:$D$404,"Contract - Lease / Finance",Register!$E$5:$E$404,"Property",Register!$P$5:$P$404,"OK") | F45: =COUNTIFS(Register!$D$5:$D$404,"Contract - Lease / Finance",Register!$E$5:$E$404,"Property",Register!$P$5:$P$404,"No date") | G45: =COUNTIFS(Register!$D$5:$D$404,"Contract - Lease / Finance",Register!$E$5:$E$404,"Property",Register!$F$5:$F$404,"?*")
...

Sheet Register
A1: Licence & Contract Register — Mitsui Thailand portfolio
A2: Type into the white columns only. Days left / Action by / Status calculate themselves. ใส่ข้อมูลเฉพาะช่องสีขาว ช่องสูตรจะคำนวณเอง
A4: No. | B4: Property | C4: Legal entity | D4: Category | E4: Renew by | F4: Item (EN) | G4: รายการ (TH) | H4: Authority / Counterparty | I4: Reference / Licence no. | J4: Issue date | K4: Expiry date | L4: Renewal cycle | M4: Notice (days) | N4: Action by | O4: Days left | P4: Status | Q4: Responsible | R4: Fee / Value (THB) | S4: Auto-renew | T4: Document location | U4: Notes | V4: SortKey
A5: =IF(F5="","",COUNTA($F$5:F5)) | B5: SR9 | C5: AMH Ratchada Co., Ltd. | D5: Licence | E5: Owner | F5: Hotel operating licence | G5: ใบอนุญาตประกอบธุรกิจโรงแรม | H5: Dept. of Provincial Administration / District Office | L5: Every 5 years | M5: 60 | N5: =IF(K5="","",K5-IF(M5="",0,M5)) | O5: =IF(K5="","",K5-TODAY()) | P5: =IF(F5="","",IF(K5="","No date",IF(O5<0,"Expired",IF(O5<=30,"Urgent",IF(O5<=90,"Due soon","OK"))))) | V5: =IF(F5="","",IF(K5="","",O5+ROW()/100000))
A6: =IF(F6="","",COUNTA($F$5:F6)) | B6: SR9 | C6: AMH Ratchada Co., Ltd. | D6: Permit | E6: Owner | F6: Building construction permit (อ.1) | G6: ใบอนุญาตก่อสร้างอาคาร (อ.1) | H6: Local authority (BMA / City Municipality) | L6: One-off | M6: 60 | N6: =IF(K6="","",K6-IF(M6="",0,M6)) | O6: =IF(K6="","",K6-TODAY()) | P6: =IF(F6="","",IF(K6="","No date",IF(O6<0,"Expired",IF(O6<=30,"Urgent",IF(O6<=90,"Due soon","OK"))))) | V6: =IF(F6="","",IF(K6="","",O6+ROW()/100000))
A7: =IF(F7="","",COUNTA($F$5:F7)) | B7: SR9 | C7: AMH Ratchada Co., Ltd. | D7: Certificate | E7: Owner | F7: Certificate of building use (อ.6) | G7: ใบรับรองการใช้อาคาร (อ.6) | H7: Local authority (BMA / City Municipality) | L7: One-off | M7: 60 | N7: =IF(K7="","",K7-IF(M7="",0,M7)) | O7: =IF(K7="","",K7-TODAY()) | P7: =IF(F7="","",IF(K7="","No date",IF(O7<0,"Expired",IF(O7<=30,"Urgent",IF(O7<=90,"Due soon","OK"))))) | V7: =IF(F7="","",IF(K7="","",O7+ROW()/100000))
A8: =IF(F8="","",COUNTA($F$5:F8)) | B8: SR9 | C8: AMH Ratchada Co., Ltd. | D8: Certificate | E8: Owner | F8: Annual building inspection report (ร.1) | G8: รายงานการตรวจสอบอาคารประจำปี (ร.1) | H8: Dept. of Public Works / local authority | L8: Annual | M8: 60 | N8: =IF(K8="","",K8-IF(M8="",0,M8)) | O8: =IF(K8="","",K8-TODAY()) | P8: =IF(F8="","",IF(K8="","No date",IF(O8<0,"Expired",IF(O8<=30,"Urgent",IF(O8<=90,"Due soon","OK"))))) | V8: =IF(F8="","",IF(K8="","",O8+ROW()/100000))
A9: =IF(F9="","",COUNTA($F$5:F9)) | B9: SR9 | C9: AMH Ratchada Co., Ltd. | D9: Certificate | E9: Owner | F9: Fire protection system inspection | G9: การตรวจสอบระบบป้องกันอัคคีภัย | H9: Licensed inspector | L9: Annual | M9: 60 | N9: =IF(K9="","",K9-IF(M9="",0,M9)) | O9: =IF(K9="","",K9-TODAY()) | P9: =IF(F9="","",IF(K9="","No date",IF(O9<0,"Expired",IF(O9<=30,"Urgent",IF(O9<=90,"Due soon","OK"))))) | V9: =IF(F9="","",IF(K9="","",O9+ROW()/100000))
A10: =IF(F10="","",COUNTA($F$5:F10)) | B10: SR9 | C10: AMH Ratchada Co., Ltd. | D10: Certificate | E10: Owner | F10: Lift / elevator inspection certificate | G10: ใบรับรองการตรวจสอบลิฟต์ | H10: Licensed engineer | L10: Annual | M10: 60 | N10: =IF(K10="","",K10-IF(M10="",0,M10)) | O10: =IF(K10="","",K10-TODAY()) | P10: =IF(F10="","",IF(K10="","No date",IF(O10<0,"Expired",IF(O10<=30,"Urgent",IF(O10<=90,"Due soon","OK"))))) | V10: =IF(F10="","",IF(K10="","",O10+ROW()/100000))
A11: =IF(F11="","",COUNTA($F$5:F11)) | B11: SR9 | C11: AMH Ratchada Co., Ltd. | D11: Certificate | E11: Owner | F11: Electrical system inspection | G11: การตรวจสอบระบบไฟฟ้า | H11: Licensed engineer | L11: Annual | M11: 60 | N11: =IF(K11="","",K11-IF(M11="",0,M11)) | O11: =IF(K11="","",K11-TODAY()) | P11: =IF(F11="","",IF(K11="","No date",IF(O11<0,"Expired",IF(O11<=30,"Urgent",IF(O11<=90,"Due soon","OK"))))) | V11: =IF(F11="","",IF(K11="","",O11+ROW()/100000))
A12: =IF(F12="","",COUNTA($F$5:F12)) | B12: SR9 | C12: AMH Ratchada Co., Ltd. | D12: Certificate | E12: Owner | F12: Generator / fuel storage permit | G12: ใบอนุญาตเครื่องกำเนิดไฟฟ้า / เก็บน้ำมันเชื้อเพลิง | H12: Dept. of Energy Business / local authority | L12: Annual | M12: 60 | N12: =IF(K12="","",K12-IF(M12="",0,M12)) | O12: =IF(K12="","",K12-TODAY()) | P12: =IF(F12="","",IF(K12="","No date",IF(O12<0,"Expired",IF(O12<=30,"Urgent",IF(O12<=90,"Due soon","OK"))))) | V12: =IF(F12="","",IF(K12="","",O12+ROW()/100000))
A13: =IF(F13="","",COUNTA($F$5:F13)) | B13: SR9 | C13: AMH Ratchada Co., Ltd. | D13: Certificate | E13: Owner | F13: Boiler / pressure vessel inspection | G13: การตรวจสอบหม้อไอน้ำ / ภาชนะรับแรงดัน | H13: Licensed engineer | L13: Annual | M13: 60 | N13: =IF(K13="","",K13-IF(M13="",0,M13)) | O13: =IF(K13="","",K13-TODAY()) | P13: =IF(F13="","",IF(K13="","No date",IF(O13<0,"Expired",IF(O13<=30,"Urgent",IF(O13<=90,"Due soon","OK"))))) | V13: =IF(F13="","",IF(K13="","",O13+ROW()/100000))
A14: =IF(F14="","",COUNTA($F$5:F14)) | B14: SR9 | C14: AMH Ratchada Co., Ltd. | D14: Certificate | E14: Owner | F14: EIA environmental monitoring report | G14: รายงานผลการปฏิบัติตามมาตรการ EIA | H14: Office of Natural Resources & Environmental Policy (ONEP) | L14: Other | M14: 60 | N14: =IF(K14="","",K14-IF(M14="",0,M14)) | O14: =IF(K14="","",K14-TODAY()) | P14: =IF(F14="","",IF(K14="","No date",IF(O14<0,"Expired",IF(O14<=30,"Urgent",IF(O14<=90,"Due soon","OK"))))) | V14: =IF(F14="","",IF(K14="","",O14+ROW()/100000))
A15: =IF(F15="","",COUNTA($F$5:F15)) | B15: SR9 | C15: AMH Ratchada Co., Ltd. | D15: Tax / Registration | E15: Owner | F15: Signage tax (billboard) | G15: ภาษีป้าย | H15: Local authority | L15: Annual | M15: 60 | N15: =IF(K15="","",K15-IF(M15="",0,M15)) | O15: =IF(K15="","",K15-TODAY()) | P15: =IF(F15="","",IF(K15="","No date",IF(O15<0,"Expired",IF(O15<=30,"Urgent",IF(O15<=90,"Due soon","OK"))))) | V15: =IF(F15="","",IF(K15="","",O15+ROW()/100000))
A16: =IF(F16="","",COUNTA($F$5:F16)) | B16: SR9 | C16: AMH Ratchada Co., Ltd. | D16: Tax / Registration | E16: Owner | F16: Land & building tax | G16: ภาษีที่ดินและสิ่งปลูกสร้าง | H16: Local authority | L16: Annual | M16: 60 | N16: =IF(K16="","",K16-IF(M16="",0,M16)) | O16: =IF(K16="","",K16-TODAY()) | P16: =IF(F16="","",IF(K16="","No date",IF(O16<0,"Expired",IF(O16<=30,"Urgent",IF(O16<=90,"Due soon","OK"))))) | V16: =IF(F16="","",IF(K16="","",O16+ROW()/100000))
... A24: =IF(F24="","",COUNTA($F$5:F24)) | B24: SR9 | C24: AMH Ratchada Co., Ltd. | D24: Contract - Management | E24: Owner | F24: Technical services / central fee agreement | G24: สัญญาค่าบริการส่วนกลาง | H24: Ascott International Management (Thailand) Ltd. | L24: Rolling / evergreen | M24: 60 | N24: =IF(K24="","",K24-IF(M24="",0,M24)) | O24: =IF(K24="","",K24-TODAY()) | P24: =IF(F24="","",IF(K24="","No date",IF(O24<0,"Expired",IF(O24<=30,"Urgent",IF(O24<=90,"Due soon","OK"))))) | V24: =IF(F24="","",IF(K24="","",O24+ROW()/100000))
A25: =IF(F25="","",COUNTA($F$5:F25)) | B25: SR9 | C25: AMH Ratchada Co., Ltd. | D25: Contract - Service | E25: Owner | F25: Lift maintenance | G25: สัญญาบำรุงรักษาลิฟต์ | L25: Annual | M25: 60 | N25: =IF(K25="","",K25-IF(M25="",0,M25)) | O25: =IF(K25="","",K25-TODAY()) | P25: =IF(F25="","",IF(K25="","No date",IF(O25<0,"Expired",IF(O25<=30,"Urgent",IF(O25<=90,"Due soon","OK"))))) | V25: =IF(F25="","",IF(K25="","",O25+ROW()/100000))
A26: =IF(F26="","",COUNTA($F$5:F26)) | B26: SR9 | C26: AMH Ratchada Co., Ltd. | D26: Contract - Service | E26: Owner | F26: HVAC / chiller maintenance | G26: สัญญาบำรุงรักษาระบบปรับอากาศ | L26: Annual | M26: 60 | N26: =IF(K26="","",K26-IF(M26="",0,M26)) | O26: =IF(K26="","",K26-TODAY()) | P26: =IF(F26="","",IF(K26="","No date",IF(O26<0,"Expired",IF(O26<=30,"Urgent",IF(O26<=90,"Due soon","OK"))))) | V26: =IF(F26="","",IF(K26="","",O26+ROW()/100000))
A27: =IF(F27="","",COUNTA($F$5:F27)) | B27: SR9 | C27: AMH Ratchada Co., Ltd. | D27: Contract - Service | E27: Owner | F27: Fire system maintenance | G27: สัญญาบำรุงรักษาระบบดับเพลิง | L27: Annual | M27: 60 | N27: =IF(K27="","",K27-IF(M27="",0,M27)) | O27: =IF(K27="","",K27-TODAY()) | P27: =IF(F27="","",IF(K27="","No date",IF(O27<0,"Expired",IF(O27<=30,"Urgent",IF(O27<=90,"Due soon","OK"))))) | V27: =IF(F27="","",IF(K27="","",O27+ROW()/100000))
A28: =IF(F28="","",COUNTA($F$5:F28)) | B28: SR9 | C28: AMH Ratchada Co., Ltd. | D28: Contract - Service | E28: Owner | F28: External audit & tax agent | G28: สัญญาผู้สอบบัญชีและที่ปรึกษาภาษี | L28: Annual | M28: 60 | N28: =IF(K28="","",K28-IF(M28="",0,M28)) | O28: =IF(K28="","",K28-TODAY()) | P28: =IF(F28="","",IF(K28="","No date",IF(O28<0,"Expired",IF(O28<=30,"Urgent",IF(O28<=90,"Due soon","OK"))))) | V28: =IF(F28="","",IF(K28="","",O28+ROW()/100000))
A29: =IF(F29="","",COUNTA($F$5:F29)) | B29: SR9 | C29: AMH Ratchada Co., Ltd. | D29: Contract - Utility | E29: Owner | F29: Electricity supply | G29: สัญญาไฟฟ้า | L29: Rolling / evergreen | M29: 60 | N29: =IF(K29="","",K29-IF(M29="",0,M29)) | O29: =IF(K29="","",K29-TODAY()) | P29: =IF(F29="","",IF(K29="","No date",IF(O29<0,"Expired",IF(O29<=30,"Urgent",IF(O29<=90,"Due soon","OK"))))) | V29: =IF(F29="","",IF(K29="","",O29+ROW()/100000))
A30: =IF(F30="","",COUNTA($F$5:F30)) | B30: SR9 | C30: AMH Ratchada Co., Ltd. | D30: Contract - Utility | E30: Owner | F30: Water supply | G30: สัญญาน้ำประปา | L30: Rolling / evergreen | M30: 60 | N30: =IF(K30="","",K30-IF(M30="",0,M30)) | O30: =IF(K30="","",K30-TODAY()) | P30: =IF(F30="","",IF(K30="","No date",IF(O30<0,"Expired",IF(O30<=30,"Urgent",IF(O30<=90,"Due soon","OK"))))) | V30: =IF(F30="","",IF(K30="","",O30+ROW()/100000))
A31: =IF(F31="","",COUNTA($F$5:F31)) | B31: SR9 | C31: AMH Ratchada Co., Ltd. | D31: Contract - Lease / Finance | E31: Owner | F31: Land / building lease | G31: สัญญาเช่าที่ดิน / อาคาร | L31: Other | M31: 60 | N31: =IF(K31="","",K31-IF(M31="",0,M31)) | O31: =IF(K31="","",K31-TODAY()) | P31: =IF(F31="","",IF(K31="","No date",IF(O31<0,"Expired",IF(O31<=30,"Urgent",IF(O31<=90,"Due soon","OK"))))) | V31: =IF(F31="","",IF(K31="","",O31+ROW()/100000))
A32: =IF(F32="","",COUNTA($F$5:F32)) | B32: SR9 | C32: AMH Ratchada Co., Ltd. | D32: Contract - Lease / Finance | E32: Owner | F32: Bank facility / loan agreement | G32: สัญญาสินเชื่อธนาคาร | L32: Other | M32: 60 | N32: =IF(K32="","",K32-IF(M32="",0,M32)) | O32: =IF(K32="","",K32-TODAY()) | P32: =IF(F32="","",IF(K32="","No date",IF(O32<0,"Expired",IF(O32<=30,"Urgent",IF(O32<=90,"Due soon","OK"))))) | V32: =IF(F32="","",IF(K32="","",O32+ROW()/100000))
A33: =IF(F33="","",COUNTA($F$5:F33)) | B33: SR9 | C33: AMH Ratchada Co., Ltd. | D33: Licence | E33: Property | F33: Hotel manager licence | G33: ใบอนุญาตผู้จัดการโรงแรม | H33: Dept. of Provincial Administration / District Office | L33: Every 5 years | M33: 60 | N33: =IF(K33="","",K33-IF(M33="",0,M33)) | O33: =IF(K33="","",K33-TODAY()) | P33: =IF(F33="","",IF(K33="","No date",IF(O33<0,"Expired",IF(O33<=30,"Urgent",IF(O33<=90,"Due soon","OK"))))) | V33: =IF(F33="","",IF(K33="","",O33+ROW()/100000))
A34: =IF(F34="","",COUNTA($F$5:F34)) | B34: SR9 | C34: AMH Ratchada Co., Ltd. | D34: Licence | E34: Property | F34: Food establishment licence | G34: ใบอนุญาตสถานที่จำหน่ายอาหาร/สะสมอาหาร | H34: Local authority (BMA / City Municipality) | L34: Annual | M34: 60 | N34: =IF(K34="","",K34-IF(M34="",0,M34)) | O34: =IF(K34="","",K34-TODAY()) | P34: =IF(F34="","",IF(K34="","No date",IF(O34<0,"Expired",IF(O34<=30,"Urgent",IF(O34<=90,"Due soon","OK"))))) | V34: =IF(F34="","",IF(K34="","",O34+ROW()/100000))
A35: =IF(F35="","",COUNTA($F$5:F35)) | B35: SR9 | C35: AMH Ratchada Co., Ltd. | D35: Licence | E35: Property | F35: Alcohol sale licence | G35: ใบอนุญาตขายสุรา | H35: Excise Department | L35: Annual | M35: 60 | N35: =IF(K35="","",K35-IF(M35="",0,M35)) | O35: =IF(K35="","",K35-TODAY()) | P35: =IF(F35="","",IF(K35="","No date",IF(O35<0,"Expired",IF(O35<=30,"Urgent",IF(O35<=90,"Due soon","OK"))))) | V35: =IF(F35="","",IF(K35="","",O35+ROW()/100000))
A36: =IF(F36="","",COUNTA($F$5:F36)) | B36: SR9 | C36: AMH Ratchada Co., Ltd. | D36: Licence | E36: Property | F36: Tobacco sale licence | G36: ใบอนุญาตขายยาสูบ | H36: Excise Department | L36: Annual | M36: 60 | N36: =IF(K36="","",K36-IF(M36="",0,M36)) | O36: =IF(K36="","",K36-TODAY()) | P36: =IF(F36="","",IF(K36="","No date",IF(O36<0,"Expired",IF(O36<=30,"Urgent",IF(O36<=90,"Due soon","OK"))))) | V36: =IF(F36="","",IF(K36="","",O36+ROW()/100000))
A37: =IF(F37="","",COUNTA($F$5:F37)) | B37: SR9 | C37: AMH Ratchada Co., Ltd. | D37: Licence | E37: Property | F37: Swimming pool / public place licence | G37: ใบอนุญาตสถานที่สาธารณะ (สระว่ายน้ำ) | H37: Local authority (BMA / City Municipality) | L37: Annual | M37: 60 | N37: =IF(K37="","",K37-IF(M37="",0,M37)) | O37: =IF(K37="","",K37-TODAY()) | P37: =IF(F37="","",IF(K37="","No date",IF(O37<0,"Expired",IF(O37<=30,"Urgent",IF(O37<=90,"Due soon","OK"))))) | V37: =IF(F37="","",IF(K37="","",O37+ROW()/100000))
A38: =IF(F38="","",COUNTA($F$5:F38)) | B38: SR9 | C38: AMH Ratchada Co., Ltd. | D38: Licence | E38: Property | F38: Radio / walkie-talkie frequency licence | G38: ใบอนุญาตวิทยุคมนาคม | H38: NBTC | L38: Annual | M38: 60 | N38: =IF(K38="","",K38-IF(M38="",0,M38)) | O38: =IF(K38="","",K38-TODAY()) | P38: =IF(F38="","",IF(K38="","No date",IF(O38<0,"Expired",IF(O38<=30,"Urgent",IF(O38<=90,"Due soon","OK"))))) | V38: =IF(F38="","",IF(K38="","",O38+ROW()/100000))
A39: =IF(F39="","",COUNTA($F$5:F39)) | B39: SR9 | C39: AMH Ratchada Co., Ltd. | D39: Licence | E39: Property | F39: Music / copyright public performance licence | G39: ใบอนุญาตเผยแพร่งานดนตรี (MCT / ลิขสิทธิ์) | H39: MCT / Phonorights / collecting societies | L39: Annual | M39: 60 | N39: =IF(K39="","",K39-IF(M39="",0,M39)) | O39: =IF(K39="","",K39-TODAY()) | P39: =IF(F39="","",IF(K39="","No date",IF(O39<0,"Expired",IF(O39<=30,"Urgent",IF(O39<=90,"Due soon","OK"))))) | V39: =IF(F39="","",IF(K39="","",O39+ROW()/100000))
A40: =IF(F40="","",COUNTA($F$5:F40)) | B40: SR9 | C40: AMH Ratchada Co., Ltd. | D40: Permit | E40: Property | F40: Waste / refuse disposal permit | G40: ใบอนุญาตกำจัดสิ่งปฏิกูลและมูลฝอย | H40: Local authority | L40: Annual | M40: 60 | N40: =IF(K40="","",K40-IF(M40="",0,M40)) | O40: =IF(K40="","",K40-TODAY()) | P40: =IF(F40="","",IF(K40="","No date",IF(O40<0,"Expired",IF(O40<=30,"Urgent",IF(O40<=90,"Due soon","OK"))))) | V40: =IF(F40="","",IF(K40="","",O40+ROW()/100000))
A41: =IF(F41="","",COUNTA($F$5:F41)) | B41: SR9 | C41: AMH Ratchada Co., Ltd. | D41: Permit | E41: Property | F41: Work permits / visas — foreign staff | G41: ใบอนุญาตทำงาน / วีซ่าพนักงานต่างชาติ | H41: Dept. of Employment / Immigration | L41: Annual | M41: 60 | N41: =IF(K41="","",K41-IF(M41="",0,M41)) | O41: =IF(K41="","",K41-TODAY()) | P41: =IF(F41="","",IF(K41="","No date",IF(O41<0,"Expired",IF(O41<=30,"Urgent",IF(O41<=90,"Due soon","OK"))))) | V41: =IF(F41="","",IF(K41="","",O41+ROW()/100000))
A42: =IF(F42="","",COUNTA($F$5:F42)) | B42: SR9 | C42: AMH Ratchada Co., Ltd. | D42: Certificate | E42: Property | F42: Swimming pool water quality test | G42: ผลตรวจคุณภาพน้ำสระว่ายน้ำ | H42: Accredited laboratory | L42: Other | M42: 60 | N42: =IF(K42="","",K42-IF(M42="",0,M42)) | O42: =IF(K42="","",K42-TODAY()) | P42: =IF(F42="","",IF(K42="","No date",IF(O42<0,"Expired",IF(O42<=30,"Urgent",IF(O42<=90,"Due soon","OK"))))) | V42: =IF(F42="","",IF(K42="","",O42+ROW()/100000))
A43: =IF(F43="","",COUNTA($F$5:F43)) | B43: SR9 | C43: AMH Ratchada Co., Ltd. | D43: Certificate | E43: Property | F43: Drinking / potable water quality test | G43: ผลตรวจคุณภาพน้ำดื่ม | H43: Accredited laboratory | L43: Annual | M43: 60 | N43: =IF(K43="","",K43-IF(M43="",0,M43)) | O43: =IF(K43="","",K43-TODAY()) | P43: =IF(F43="","",IF(K43="","No date",IF(O43<0,"Expired",IF(O43<=30,"Urgent",IF(O43<=90,"Due soon","OK"))))) | V43: =IF(F43="","",IF(K43="","",O43+ROW()/100000))
A44: =IF(F44="","",COUNTA($F$5:F44)) | B44: SR9 | C44: AMH Ratchada Co., Ltd. | D44: Certificate | E44: Property | F44: Wastewater treatment monitoring report | G44: รายงานผลการตรวจวัดคุณภาพน้ำทิ้ง | H44: Dept. of Pollution Control / local authority | L44: Other | M44: 60 | N44: =IF(K44="","",K44-IF(M44="",0,M44)) | O44: =IF(K44="","",K44-TODAY()) | P44: =IF(F44="","",IF(K44="","No date",IF(O44<0,"Expired",IF(O44<=30,"Urgent",IF(O44<=90,"Due soon","OK"))))) | V44: =IF(F44="","",IF(K44="","",O44+ROW()/100000))
... A52: =IF(F52="","",COUNTA($F$5:F52)) | B52: SR9 | C52: AMH Ratchada Co., Ltd. | D52: Contract - Service | E52: Property | F52: F&B outlet / catering operator | G52: สัญญาผู้ประกอบการอาหารและเครื่องดื่ม | H52: DK Wow Venture Co., Ltd. | L52: Annual | M52: 60 | N52: =IF(K52="","",K52-IF(M52="",0,M52)) | O52: =IF(K52="","",K52-TODAY()) | P52: =IF(F52="","",IF(K52="","No date",IF(O52<0,"Expired",IF(O52<=30,"Urgent",IF(O52<=90,"Due soon","OK"))))) | V52: =IF(F52="","",IF(K52="","",O52+ROW()/100000))
A53: =IF(F53="","",COUNTA($F$5:F53)) | B53: SR9 | C53: AMH Ratchada Co., Ltd. | D53: Contract - Service | E53: Property | F53: Security services | G53: สัญญาบริการรักษาความปลอดภัย | L53: Annual | M53: 60 | N53: =IF(K53="","",K53-IF(M53="",0,M53)) | O53: =IF(K53="","",K53-TODAY()) | P53: =IF(F53="","",IF(K53="","No date",IF(O53<0,"Expired",IF(O53<=30,"Urgent",IF(O53<=90,"Due soon","OK"))))) | V53: =IF(F53="","",IF(K53="","",O53+ROW()/100000))
A54: =IF(F54="","",COUNTA($F$5:F54)) | B54: SR9 | C54: AMH Ratchada Co., Ltd. | D54: Contract - Service | E54: Property | F54: Cleaning / housekeeping outsource | G54: สัญญาบริการทำความสะอาด | L54: Annual | M54: 60 | N54: =IF(K54="","",K54-IF(M54="",0,M54)) | O54: =IF(K54="","",K54-TODAY()) | P54: =IF(F54="","",IF(K54="","No date",IF(O54<0,"Expired",IF(O54<=30,"Urgent",IF(O54<=90,"Due soon","OK"))))) | V54: =IF(F54="","",IF(K54="","",O54+ROW()/100000))
A55: =IF(F55="","",COUNTA($F$5:F55)) | B55: SR9 | C55: AMH Ratchada Co., Ltd. | D55: Contract - Service | E55: Property | F55: Pest control | G55: สัญญากำจัดแมลง | L55: Annual | M55: 60 | N55: =IF(K55="","",K55-IF(M55="",0,M55)) | O55: =IF(K55="","",K55-TODAY()) | P55: =IF(F55="","",IF(K55="","No date",IF(O55<0,"Expired",IF(O55<=30,"Urgent",IF(O55<=90,"Due soon","OK"))))) | V55: =IF(F55="","",IF(K55="","",O55+ROW()/100000))
...

Sheet Lists
A1: Dropdown lists — used by the Register. Edit here to change the choices.
A3: Property | C3: Category | E3: Renewal cycle | G3: Auto-renew | I3: Status (reference) | K3: Property | L3: Full name | M3: Legal entity | O3: Renew by
A4: SR9 | C4: Licence | E4: Annual | G4: Yes | I4: Expired | K4: SR9 | L4: Somerset Rama 9 Bangkok | M4: AMH Ratchada Co., Ltd. | O4: Owner
A5: AES | C5: Permit | E5: Every 2 years | G5: No | I5: Urgent | K5: AES | L5: Ascott Embassy Sathorn Bangkok | M5: AMH Sathorn Co., Ltd. | O5: Property
A6: LYF | C6: Certificate | E6: Every 3 years | I6: Due soon | K6: LYF | L6: lyf Sukhumvit 8 Bangkok | M6: AMH Sukhumvit 8 Co., Ltd.
A7: SP | C7: Tax / Registration | E7: Every 5 years | I7: OK | K7: SP | L7: Somerset Pattaya | M7: AMH Pattaya Co., Ltd.
C8: Insurance | E8: One-off | I8: No date
C9: Contract - Management | E9: Rolling / evergreen
C10: Contract - OTA | E10: Monthly
C11: Contract - Service | E11: Other
C12: Contract - Utility
C13: Contract - Lease / Finance
