Workbook
Name \: OFFSET(Full_Print,0,0,[1]!Last_Row)
Name \: OFFSET(Full_Print,0,0,[1]!Last_Row)
Name \: OFFSET(Full_Print,0,0,[1]!Last_Row)
Name \: OFFSET(Full_Print,0,0,[1]!Last_Row)
Name \0: '[2]C-1'!$R$2
Name \200: #REF!
Name \a: '[3]ลูกหนี้(เก่า)'!#REF!
Name \b: '[3]ลูกหนี้(เก่า)'!#REF!
Name \c: '[3]ลูกหนี้(เก่า)'!#REF!
Name \d: #REF!
Name \e: #REF!
Name \f: #REF!
Name \g: #REF!
Name \h: #REF!
Name \i: #REF!
Name \j: #REF!
Name \k: #REF!
Name \l: #REF!
Name \m: #REF!
Name \n: #N/A
Name \o: #REF!
Name \p: #N/A
Name \q: #N/A
Name \r: [4]FSALES!#REF!
Name \s: #REF!
Name \t: '[5]ELEC45-01'!#REF!
Name \u: '[3]ลูกหนี้(เก่า)'!#REF!
Name \v: #REF!
Name \w: #N/A
Name \x: #REF!
Name \y: #REF!
Name \z: #REF!
Name _.._Specification_name__KAL2: #REF!
Name _??: '[7]????-??'!#REF!
Name _???: '[8]????-??'!#REF!
Name _?????: '[9]?????'!$C$6:$C$34
Name __??: '[10]????-??'!#REF!
Name __???: '[8]????-??'!#REF!
Name __?????: '[11]?????'!$C$6:$C$34
Name ___??: '[10]????-??'!#REF!
Name ___???: '[8]????-??'!#REF!
Name ___?????: '[11]?????'!$C$6:$C$34
Name ____??: '[12]????-??'!#REF!
Name ____???: '[8]????-??'!#REF!
Name ____?????: '[13]?????'!$C$6:$C$34
Name ___________________dkk1: #REF!
Name ___________________dkk2: #REF!
Name ___________________exp10: #REF!
Name ___________________exp11: #REF!
Name ___________________exp12: #REF!
Name ___________________EXP22: #REF!
Name ___________________exp5: #REF!
Name ___________________exp7: #REF!
Name ___________________exp8: #REF!
Name ___________________exp9: #REF!
Name ___________________lit1: #REF!
Name ___________________lit2: #REF!
Name ___________________SCB1: '[14]SCB 1 - Current'!$F$10
Name ___________________SCB2: '[14]SCB 2 - Current'!$F$11
Name ___________________Us1: #REF!

Sheet result FY25
C3: YTD performance
C4: Unit: kTHB
C5: SR9 | D5: Compare with MF Projection | I5: ATB | J5: Compare with MF Projection | O5: AES | P5: Compare with MF Projection | U5: lyf | V5: Compare with MF Projection | AA5: SP | AB5: Compare with MF Projection | AG5: Portfolio | AH5: Compare with MF Projection
D6: Ascott BP | E6: MF Projection | F6: Actual | G6: % change | J6: Ascott BP | K6: MF Projection | L6: Actual | M6: % change | P6: Ascott BP | Q6: MF Projection | R6: Actual | S6: % change | V6: Ascott BP | W6: MF Projection | X6: Actual | Y6: % change | AB6: Ascott BP | AC6: MF Projection | AD6: Actual | AE6: % change | AH6: Ascott BP | AI6: MF Projection | AJ6: Actual | AK6: % change
C7: OCC | D7: =(D37*31+E37*28+F37*31+G37*30+H37*31+I37*30+J37*31+K37*31+L37*30+M37*31+N37*30+O37*31)/365 -> 0.84442569 | E7: =(D41*31+E41*28+F41*31+G41*30+H41*31+I41*30+J41*31+K41*31+L41*30+M41*31+N41*30+O41*31)/(31+28+31+30+31+30+31+31+30+31+30+31) -> 0.75293443 | F7: =(D45*31+E45*28+F45*31+G45*30+H45*31+I45*30+J45*31+K45*31+L45*30+M45*31+N45*30+O45*31)/(31+28+31+30+31+30+31+31+30+31+30+31) -> 0.78250269 | G7: 0.039270704 | H7: =F7=P45 -> TRUE | I7: OCC | J7: 0.79402509 | K7: 0.69966099 | L7: 0.72463502 | M7: 0.035694472 | N7: =L7=P67 -> TRUE | O7: OCC | P7: 0.81647945 | Q7: 0.67088875 | R7: =(D89*31+E89*28+F89*31+G89*30+H89*31+I89*30+J89*31+K89*31+L89*30+M89*31+N89*30+O89*31)/(31+28+31+30+31+30+31+31+30+31+30+31) -> 0.70592068 | S7: 0.052217198 | T7: =R7=P89 -> TRUE | U7: OCC | V7: 0.78157674 | W7: 0.78725156 | X7: =(D111*31+E111*28+F111*31+G111*30+H111*31+I111*30+J111*31+K111*31+L111*30+M111*31+N111*30+O111*31)/(31+28+31+30+31+30+31+31+30+31+30+31) -> 0.82739085 | Y7: 0.050986612 | AA7: OCC | AB7: =(D125*31+E125*28+F125*31+G125*30+H125*31+I125*30+J125*31+K125*31+L125*30+M125*31+N125*30+O125*31)/(31+28+31+30+31+30+31+31+30+31+30+31) -> 0.7874091 | AC7: =(D129*31+E129*28+F129*31+G129*30+H129*31+I129*30+J129*31+K129*31+L129*30+M129*31+N129*30)/(31+28+31+30+31+30+31+31+30+31+30+31) -> 0.62414675 | AD7: =(D133*31+E133*28+F133*31+G133*30+H133*31+I133*30+J133*31+K133*31+L133*30+M133*31+N133*30+O133*31)/(31+28+31+30+31+30+31+31+30+31+30+31) -> 0.7187079 | AE7: =(AD7-AC7)/AC7 -> 0.15150468 | AG7: OCC | AH7: 0.8087677 | AI7: 0.70248041 | AJ7: =(F7*$E$33+L7*$E$55+R7*$E$77+X7*$E$99+AD7*$E$121)/SUM($E$33,$E$55,$E$77,$E$99,$E$121) -> 0.74487611 | AK7: 0.060351439
C8: ADR | D8: 3185.053 | E8: =(D42*31+E42*28+F42*31+G42*30+H42*31+I42*30+J42*31+K42*31+L42*30+M42*31+N42*30+O42*31)/(31+28+31+30+31+30+31+31+30+31+30+31) -> 2838.0497 | F8: =(D48*31+E48*28+F48*31+G48*30+H48*31+I48*30+J48*31+K48*31+L48*30+M48*31+N48*30+O48*31)/365 -> 2929.1183 | G8: 0.029879645 | H8: =F8=P48 -> TRUE | I8: ADR | J8: 4119.8256 | K8: 3484.3586 | L8: 3534.0011 | M8: 0.014247232 | N8: =L8=P70 -> TRUE | O8: ADR | P8: 4067.2988 | Q8: 3152.293 | R8: =(D92*31+E92*28+F92*31+G92*30+H92*31+I92*30+J92*31+K92*31+L92*30+M92*31+N92*30+O92*31)/(31+28+31+30+31+30+31+31+30+31+30+31) -> 3597.8954 | S8: 0.1413582 | T8: =R8=P92 -> TRUE | U8: ADR | V8: 1674.411 | W8: 1398.228 | X8: =(D114*31+E114*28+F114*31+G114*30+H114*31+I114*30+J114*31+K114*31+L114*30+M114*31+N114*30+O114*31)/(31+28+31+30+31+30+31+31+30+31+30+31) -> 1377.6142 | Y8: -0.014742813 | AA8: ADR | AB8: =(D126*31+E126*28+F126*31+G126*30+H126*31+I126*30+J126*31+K126*31+L126*30+M126*31)/(31+28+31+30+31+30+31+31+30+31+30+31) -> 3421.7709 | AC8: =(D130*31+E130*28+F130*31+G130*30+H130*31+I130*30+J130*31+K130*31+L130*30+M130*31)/(31+28+31+30+31+30+31+31+30+31+30+31) -> 3011.0882 | AD8: =(D136*31+E136*28+F136*31+G136*30+H136*31+I136*30+J136*31+K136*31+L136*30+M136*31+N136*30+O136*31)/(31+28+31+30+31+30+31+31+30+31+30+31) -> 3813.0355 | AE8: =(AD8-AC8)/AC8 -> 0.26633139 | AG8: ADR | AH8: 3490.4516 | AI8: 2916.4422 | AJ8: =(F8*F7*$E$33+L8*L7*$E$55+R8*R7*$E$77+X8*X7*$E$99+AD8*AD7*$E$121)/SUM(F7*$E$33,L7*$E$55,R7*$E$77,X7*$E$99,AD7*$E$121) -> 3179.5438 | AK8: 0.089657766
C9: RevPar | D9: =D8*D7 -> 2689.5406 | E9: =E8*E7 -> 2136.8653 | F9: =F8*F7 -> 2292.0429 | G9: 0.070323744 | I9: RevPar | J9: =J8*J7 -> 3271.2449 | K9: =K8*K7 -> 2437.8698 | L9: =L8*L7 -> 2560.8609 | M9: 0.050450252 | O9: RevPar | P9: =P8*P7 -> 3320.8659 | Q9: =Q8*Q7 -> 2114.8379 | R9: =R7*R8 -> 2539.8288 | S9: 0.20095673 | U9: RevPar | V9: =V7*V8 -> 1308.6807 | W9: =W7*W8 -> 1100.7572 | X9: =X7*X8 -> 1139.8253 | Y9: 0.035492113 | AA9: RevPar | AB9: =AB7*AB8 -> 2694.3336 | AC9: =AC7*AC8 -> 1879.3609 | AD9: =AD7*AD8 -> 2740.4587 | AE9: =(AD9-AC9)/AC9 -> 0.45818652 | AG9: RevPar | AH9: =AH7*AH8 -> 2822.9645 | AI9: =AI7*AI8 -> 2048.7435 | AJ9: =AJ7*AJ8 -> 2368.3662 | AK9: 0.15542018
C10: GOP Margin | D10: 0.58766999 | E10: 0.5741623 | F10: 0.57305356 | G10: -0.001931055 | I10: GOP Margin | J10: 0.58157673 | K10: 0.55172634 | L10: 0.55279341 | M10: 0.0019340494 | O10: GOP Margin | P10: 0.56835325 | Q10: 0.51270909 | R10: =R14/R12 -> 0.52329728 | S10: 0.020651471 | U10: GOP Margin | V10: 0.49173705 | W10: 0.47894649 | X10: =X14/X12 -> 0.49149722 | Y10: 0.026204857 | AA10: GOP Margin | AB10: =AB14/AB12 -> 0.57713849 | AC10: =AC14/AC12 -> 0.54830574 | AD10: =AD14/AD12 -> 0.55590946 | AE10: =(AD10-AC10)/AC10 -> 0.013867669 | AG10: GOP Margin | AH10: 0.57425666 | AI10: 0.5438053 | AJ10: =AJ14/AJ12 -> 0.54623705 | AK10: 0.0081316714
C12: Revenue | D12: 4.8923854e+08 | E12: 3.7349996e+08 | F12: 3.9452489e+08 | G12: 0.056291667 | I12: Revenue | J12: 5.6060193e+08 | K12: 4.1766098e+08 | L12: 4.4152883e+08 | M12: 0.05714648 | O12: Revenue | P12: 4.9719146e+08 | Q12: 3.5215685e+08 | R12: 3.8133572e+08 | S12: 0.082857612 | U12: Revenue | V12: 89376876 | W12: 79910226 | X12: 86351160 | Y12: 0.080602124 | AA12: Revenue | AB12: 3.9989037e+08 | AC12: 3.0865798e+08 | AD12: 3.3777501e+08 | AE12: 0.094334287 | AG12: Revenue | AH12: 2.0362992e+09 | AI12: 1.531886e+09 | AJ12: 1.3037406e+09 | AK12: -0.14893104
C13: OPEX | D13: -2.0171482e+08 | E13: -1.5892375e+08 | F13: -1.68441e+08 | G13: 0.059885626 | I13: OPEX | J13: -2.3232876e+08 | K13: -1.8761864e+08 | L13: -1.974546e+08 | M13: 0.052425315 | O13: OPEX | P13: -2.1355353e+08 | Q13: -1.7202664e+08 | R13: -1.8178378e+08 | S13: 0.056718716 | U13: OPEX | V13: -44921854 | W13: -41774081 | X13: -43909805 | Y13: 0.051125591 | AA13: OPEX | AB13: -1.6909825e+08 | AC13: -1.3941904e+08 | AD13: -1.5000269e+08 | AE13: 0.075912503 | AG13: OPEX | AH13: -8.6161721e+08 | AI13: -6.9976215e+08 | AJ13: -5.9158918e+08 | AK13: -0.15458534
C14: GOP | D14: 2.8752372e+08 | E14: 2.1457621e+08 | F14: 2.2608389e+08 | G14: 0.053629836 | I14: GOP | J14: 3.2827317e+08 | K14: 2.3004234e+08 | L14: 2.4407423e+08 | M14: 0.060996981 | O14: GOP | P14: 2.8363792e+08 | Q14: 1.801302e+08 | R14: 1.9955195e+08 | S14: 0.10782059 | U14: GOP | V14: 44455022 | W14: 38136145 | X14: 42441355 | Y14: 0.11289052 | AA14: GOP | AB14: 2.3079213e+08 | AC14: 1.6923894e+08 | AD14: 1.8777232e+08 | AE14: 0.10951015 | AG14: GOP | AH14: 1.174682e+09 | AI14: 8.3212383e+08 | AJ14: 7.1215142e+08 | AK14: -0.14417615 | AN14: 30888702
C15: JV expense | D15: -1.2583485e+08 | E15: -1.11362e+08 | F15: -1.1400689e+08 | G15: 0.023750455 | I15: JV expense | J15: -1.6865831e+08 | K15: -1.6248844e+08 | L15: -1.7492324e+08 | M15: 0.076527288 | O15: JV expense | P15: -1.4342121e+08 | Q15: -1.2066449e+08 | R15: -1.2997337e+08 | S15: 0.077146818 | U15: JV expense | V15: -27040640 | W15: -26570816 | X15: -26396203 | Y15: -0.006571612 | AA15: JV expense | AB15: -83954326 | AC15: -70240913 | AD15: -79989511 | AE15: 0.13878803 | AG15: JV expense | AH15: -5.4890933e+08 | AI15: -4.9132665e+08 | AJ15: -4.4529971e+08 | AK15: -0.093678914 | AN15: 4413117.5
C16: EBIT | D16: 1.6168887e+08 | E16: 1.0321421e+08 | F16: 1.12077e+08 | G16: 0.085867912 | I16: EBIT | J16: 1.5961486e+08 | K16: 67553903 | L16: 69150992 | M16: 0.023641697 | O16: EBIT | P16: 1.4021671e+08 | Q16: 59465713 | R16: 69578577 | S16: 0.17006209 | U16: EBIT | V16: 17414383 | W16: 11565329 | X16: 16045152 | Y16: 0.38734932 | AA16: EBIT | AB16: 1.468378e+08 | AC16: 98998027 | AD16: 1.0778281e+08 | AE16: 0.088736963 | AG16: EBIT | AH16: 6.2577263e+08 | AI16: 3.4079718e+08 | AJ16: 2.6685172e+08 | AK16: -0.21697792 | AN16: 35301819
B20: Portfolio | D20: 2025 | P20: Avg | R20: Overall GOP / EBIT | T20: 2025 | AF20: Total
D21: Jan | E21: Feb | F21: Mar | G21: Apr | H21: May | I21: Jun | J21: Jul | K21: Aug | L21: Sep | M21: Oct | N21: Nov | O21: Dec | T21: Jan | U21: Feb | V21: Mar | W21: Apr | X21: May | Y21: Jun | Z21: Jul | AA21: Aug | AB21: Sep | AC21: Oct | AD21: Nov | AE21: Dec
B22: Key Available | D22: =E33+E55+E77+E99+E121 -> 1809 | E22: =D22 -> 1809 | F22: =E22 -> 1809 | G22: =F22 -> 1809 | H22: =G22 -> 1809 | I22: =H22 -> 1809 | J22: =I22 -> 1809 | K22: =J22 -> 1809 | L22: =K22 -> 1809 | ... O22: =N22 -> 1809 | R22: Ascott BP GOP | T22: =SUM(T40,T62,T84,T106,T128) -> 1.0590519e+08 | U22: =SUM(U40,U62,U84,U106,U128) -> 1.0396394e+08 | V22: =SUM(V40,V62,V84,V106,V128) -> 93340290 | W22: =SUM(W40,W62,W84,W106,W128) -> 97710543 | X22: =SUM(X40,X62,X84,X106,X128) -> 81498889 | Y22: =SUM(Y40,Y62,Y84,Y106,Y128) -> 90769038 | Z22: =SUM(Z40,Z62,Z84,Z106,Z128) -> 1.1280233e+08 | AA22: =SUM(AA40,AA62,AA84,AA106,AA128) -> 1.1093336e+08 | ... AD22: =SUM(AD40,AD62,AD84,AD106,AD128) -> 1.0682416e+08 | AE22: 1.1295487e+08 | AF22: =SUM(T22:AE22) -> 1.174682e+09
B23: Ascott BP OCC | D23: =(D37*$E$33+D59*$E$55+D81*$E$77+D103*$E$99+D125*$E$121)/SUM($E$33,$E$55,$E$77,$E$99,$E$121) -> 0.82723844 | E23: =(E37*$E$33+E59*$E$55+E81*$E$77+E103*$E$99+E125*$E$121)/SUM($E$33,$E$55,$E$77,$E$99,$E$121) -> 0.88017689 | F23: =(F37*$E$33+F59*$E$55+F81*$E$77+F103*$E$99+F125*$E$121)/SUM($E$33,$E$55,$E$77,$E$99,$E$121) -> 0.80247985 | G23: =(G37*$E$33+G59*$E$55+G81*$E$77+G103*$E$99+G125*$E$121)/SUM($E$33,$E$55,$E$77,$E$99,$E$121) -> 0.80520865 | H23: =(H37*$E$33+H59*$E$55+H81*$E$77+H103*$E$99+H125*$E$121)/SUM($E$33,$E$55,$E$77,$E$99,$E$121) -> 0.76246312 | I23: =(I37*$E$33+I59*$E$55+I81*$E$77+I103*$E$99+I125*$E$121)/SUM($E$33,$E$55,$E$77,$E$99,$E$121) -> 0.81128518 | J23: =(J37*$E$33+J59*$E$55+J81*$E$77+J103*$E$99+J125*$E$121)/SUM($E$33,$E$55,$E$77,$E$99,$E$121) -> 0.86124196 | K23: =(K37*$E$33+K59*$E$55+K81*$E$77+K103*$E$99+K125*$E$121)/SUM($E$33,$E$55,$E$77,$E$99,$E$121) -> 0.85387355 | ... O23: =(O37*$E$33+O59*$E$55+O81*$E$77+O103*$E$99+O125*$E$121)/SUM($E$33,$E$55,$E$77,$E$99,$E$121) -> 0.8179414 | P23: =(D23*31+E23*28+F23*31+G23*30+H23*31+I23*30+J23*31+K23*31+L23*30+M23*31+N23*30+O23*31)/365 -> 0.8087677 | R23: MF Projection GOP | T23: =SUM(T41,T63,T85,T107,T129) -> 1.0874488e+08 | U23: =SUM(U41,U63,U85,U107,U129) -> 84829796 | V23: =SUM(V41,V63,V85,V107,V129) -> 66251300 | W23: =SUM(W41,W63,W85,W107,W129) -> 65881450 | X23: =SUM(X41,X63,X85,X107,X129) -> 60665411 | Y23: =SUM(Y41,Y63,Y85,Y107,Y129) -> 54936996 | Z23: =SUM(Z41,Z63,Z85,Z107,Z129) -> 72160205 | AA23: =SUM(AA41,AA63,AA85,AA107,AA129) -> 69030886 | ... AD23: =SUM(AD41,AD63,AD85,AD107,AD129) -> 69749394 | AE23: 77246729 | AF23: =SUM(T23:AE23) -> 8.3212383e+08
B24: Ascott BP ADR | D24: =(D38*$E$33*D37+D60*$E$55*D59+$E$77*D81*D82+$E$99*D103*D104+$E$121*D125*D126)/SUM($E$33*D37,$E$55*D59,$E$77*D81,$E$99*D103,$E$121*D125) -> 3711.9142 | E24: =(E38*$E$33*E37+E60*$E$55*E59+$E$77*E81*E82+$E$99*E103*E104+$E$121*E125*E126)/SUM($E$33*E37,$E$55*E59,$E$77*E81,$E$99*E103,$E$121*E125) -> 3790.0322 | F24: =(F38*$E$33*F37+F60*$E$55*F59+$E$77*F81*F82+$E$99*F103*F104+$E$121*F125*F126)/SUM($E$33*F37,$E$55*F59,$E$77*F81,$E$99*F103,$E$121*F125) -> 3546.3943 | G24: =(G38*$E$33*G37+G60*$E$55*G59+$E$77*G81*G82+$E$99*G103*G104+$E$121*G125*G126)/SUM($E$33*G37,$E$55*G59,$E$77*G81,$E$99*G103,$E$121*G125) -> 3758.4343 | H24: =(H38*$E$33*H37+H60*$E$55*H59+$E$77*H81*H82+$E$99*H103*H104+$E$121*H125*H126)/SUM($E$33*H37,$E$55*H59,$E$77*H81,$E$99*H103,$E$121*H125) -> 3415.0058 | I24: =(I38*$E$33*I37+I60*$E$55*I59+$E$77*I81*I82+$E$99*I103*I104+$E$121*I125*I126)/SUM($E$33*I37,$E$55*I59,$E$77*I81,$E$99*I103,$E$121*I125) -> 3553.0857 | J24: =(J38*$E$33*J37+J60*$E$55*J59+$E$77*J81*J82+$E$99*J103*J104+$E$121*J125*J126)/SUM($E$33*J37,$E$55*J59,$E$77*J81,$E$99*J103,$E$121*J125) -> 3722.0201 | K24: =(K38*$E$33*K37+K60*$E$55*K59+$E$77*K81*K82+$E$99*K103*K104+$E$121*K125*K126)/SUM($E$33*K37,$E$55*K59,$E$77*K81,$E$99*K103,$E$121*K125) -> 3725.8559 | ... O24: =(O38*$E$33*O37+O60*$E$55*O59+$E$77*O81*O82+$E$99*O103*O104+$E$121*O125*O126)/SUM($E$33*O37,$E$55*O59,$E$77*O81,$E$99*O103,$E$121*O125) -> 3787.6355 | P24: =(D24*31+E24*28+F24*31+G24*30+H24*31+I24*30+J24*31+K24*31+L24*30+M24*31+N24*30+O24*31)/365 -> 3604.2108 | R24: GOP | T24: =SUM(T42,T64,T86,T108,T130) -> 1.0874488e+08 | U24: =SUM(U42,U64,U86,U108,U130) -> 84829796 | V24: =SUM(V42,V64,V86,V108,V130) -> 66251300 | W24: =SUM(W42,W64,W86,W108,W130) -> 65881450 | X24: =SUM(X42,X64,X86,X108,X130) -> 60665411 | Y24: =SUM(Y42,Y64,Y86,Y108,Y130) -> 54936996 | Z24: =SUM(Z42,Z64,Z86,Z108,Z130) -> 76597600 | AA24: =SUM(AA42,AA64,AA86,AA108,AA130) -> 80493575 | ... AD24: =SUM(AD42,AD64,AD86,AD108,AD130) -> 82074071 | AE24: 1.0183326e+08 | AF24: =SUM(T24:AE24) -> 8.9992375e+08
B25: Ascott BP RevPar | D25: =D23*D24 -> 3070.6381 | E25: =E23*E24 -> 3335.8988 | F25: =F23*F24 -> 2845.91 | G25: =G23*G24 -> 3026.3238 | H25: =H23*H24 -> 2603.816 | I25: =I23*I24 -> 2882.5658 | J25: =J23*J24 -> 3205.5599 | K25: =K23*K24 -> 3181.4098 | ... P25: =P23*P24 -> 2914.9692 | R25: Ascott BP EBIT | T25: =SUM(T46,T68,T90,T112,T134) -> 59515077 | U25: =SUM(U46,U68,U90,U112,U134) -> 57748940 | V25: =SUM(V46,V68,V90,V112,V134) -> 47934545 | W25: =SUM(W46,W68,W90,W112,W134) -> 51946946 | X25: =SUM(X46,X68,X90,X112,X134) -> 37095664 | Y25: =SUM(Y46,Y68,Y90,Y112,Y134) -> 45586850 | Z25: =SUM(Z46,Z68,Z90,Z112,Z134) -> 65855049 | AA25: =SUM(AA46,AA68,AA90,AA112,AA134) -> 64120553 | ... AD25: =SUM(AD46,AD68,AD90,AD112,AD134) -> 60373028 | AE25: 65985930 | AF25: =SUM(T25:AE25) -> 6.2577263e+08
B26: MF Projection OCC | D26: =(D41*$E$33+D63*$E$55+D85*$E$77+D107*$E$99+D129*$E$121)/SUM($E$33,$E$55,$E$77,$E$99,$E$121) -> 0.8406497 | E26: =(E41*$E$33+E63*$E$55+E85*$E$77+E107*$E$99+E129*$E$121)/SUM($E$33,$E$55,$E$77,$E$99,$E$121) -> 0.82892743 | F26: =(F41*$E$33+F63*$E$55+F85*$E$77+F107*$E$99+F129*$E$121)/SUM($E$33,$E$55,$E$77,$E$99,$E$121) -> 0.66754043 | G26: =(G41*$E$33+G63*$E$55+G85*$E$77+G107*$E$99+G129*$E$121)/SUM($E$33,$E$55,$E$77,$E$99,$E$121) -> 0.66679565 | H26: =(H41*$E$33+H63*$E$55+H85*$E$77+H107*$E$99+H129*$E$121)/SUM($E$33,$E$55,$E$77,$E$99,$E$121) -> 0.67854277 | I26: =(I41*$E$33+I63*$E$55+I85*$E$77+I107*$E$99+I129*$E$121)/SUM($E$33,$E$55,$E$77,$E$99,$E$121) -> 0.66412383 | J26: =(J41*$E$33+J63*$E$55+J85*$E$77+J107*$E$99+J129*$E$121)/SUM($E$33,$E$55,$E$77,$E$99,$E$121) -> 0.75306098 | K26: =(K41*$E$33+K63*$E$55+K85*$E$77+K107*$E$99+K129*$E$121)/SUM($E$33,$E$55,$E$77,$E$99,$E$121) -> 0.71584998 | ... O26: =(O41*$E$33+O63*$E$55+O85*$E$77+O107*$E$99+O129*$E$121)/SUM($E$33,$E$55,$E$77,$E$99,$E$121) -> 0.75880736 | P26: =(D26*31+E26*28+F26*31+G26*30+H26*31+I26*30+J26*31+K26*31+L26*30+M26*31+N26*30+O26*31)/365 -> 0.71185678 | R26: MF Projection EBIT | T26: =SUM(T47,T69,T91,T113,T135) -> 62961089 | U26: =SUM(U47,U69,U91,U113,U135) -> 42824009 | V26: =SUM(V47,V69,V91,V113,V135) -> 24042174 | W26: =SUM(W47,W69,W91,W113,W135) -> 25051019 | X26: =SUM(X47,X69,X91,X113,X135) -> 17197184 | Y26: =SUM(Y47,Y69,Y91,Y113,Y135) -> 12899417 | Z26: =SUM(Z47,Z69,Z91,Z113,Z135) -> 31592298 | AA26: =SUM(AA47,AA69,AA91,AA113,AA135) -> 37914927 | ... AD26: =SUM(AD47,AD69,AD91,AD113,AD135) -> 39297058 | AE26: 35301888 | AF26: =SUM(T26:AE26) -> 3.6598599e+08
B27: MF Projection ADR | D27: =(D42*$E$33*D41+D64*$E$55*D63+$E$77*D85*D86+$E$99*D107*D108+$E$121*D129*D130)/SUM($E$33*D41,$E$55*D63,$E$77*D85,$E$99*D107,$E$121*D129) -> 3666.2182 | E27: =(E42*$E$33*E41+E64*$E$55*E63+$E$77*E85*E86+$E$99*E107*E108+$E$121*E129*E130)/SUM($E$33*E41,$E$55*E63,$E$77*E85,$E$99*E107,$E$121*E129) -> 3450.2617 | F27: =(F42*$E$33*F41+F64*$E$55*F63+$E$77*F85*F86+$E$99*F107*F108+$E$121*F129*F130)/SUM($E$33*F41,$E$55*F63,$E$77*F85,$E$99*F107,$E$121*F129) -> 3170.9934 | G27: =(G42*$E$33*G41+G64*$E$55*G63+$E$77*G85*G86+$E$99*G107*G108+$E$121*G129*G130)/SUM($E$33*G41,$E$55*G63,$E$77*G85,$E$99*G107,$E$121*G129) -> 3286.9449 | H27: =(H42*$E$33*H41+H64*$E$55*H63+$E$77*H85*H86+$E$99*H107*H108+$E$121*H129*H130)/SUM($E$33*H41,$E$55*H63,$E$77*H85,$E$99*H107,$E$121*H129) -> 2996.1266 | I27: =(I42*$E$33*I41+I64*$E$55*I63+$E$77*I85*I86+$E$99*I107*I108+$E$121*I129*I130)/SUM($E$33*I41,$E$55*I63,$E$77*I85,$E$99*I107,$E$121*I129) -> 2972.6018 | J27: =(J42*$E$33*J41+J64*$E$55*J63+$E$77*J85*J86+$E$99*J107*J108+$E$121*J129*J130)/SUM($E$33*J41,$E$55*J63,$E$77*J85,$E$99*J107,$E$121*J129) -> 3037.6327 | K27: =(K42*$E$33*K41+K64*$E$55*K63+$E$77*K85*K86+$E$99*K107*K108+$E$121*K129*K130)/SUM($E$33*K41,$E$55*K63,$E$77*K85,$E$99*K107,$E$121*K129) -> 3056.6866 | ... O27: =(O42*$E$33*O41+O64*$E$55*O63+$E$77*O85*O86+$E$99*O107*O108+$E$121*O129*O130)/SUM($E$33*O41,$E$55*O63,$E$77*O85,$E$99*O107,$E$121*O129) -> 3198.0453 | P27: =(D27*31+E27*28+F27*31+G27*30+H27*31+I27*30+J27*31+K27*31+L27*30+M27*31+N27*30+O27*31)/365 -> 3082.6497 | R27: EBIT | T27: =SUM(T48,T70,T92,T114,T136) -> 62874148 | U27: =SUM(U48,U70,U92,U114,U136) -> 42910949 | V27: =SUM(V48,V70,V92,V114,V136) -> 24042174 | W27: =SUM(W48,W70,W92,W114,W136) -> 25051019 | X27: =SUM(X48,X70,X92,X114,X136) -> 17197184 | Y27: =SUM(Y48,Y70,Y92,Y114,Y136) -> 12899417 | Z27: =SUM(Z48,Z70,Z92,Z114,Z136) -> 31592298 | AA27: =SUM(AA48,AA70,AA92,AA114,AA136) -> 37914927 | ... AD27: =SUM(AD48,AD70,AD92,AD114,AD136) -> 39297054 | AE27: 42089386 | AF27: =SUM(T27:AE27) -> 3.7277348e+08
B28: MF Projection RevPar | D28: =D26*D27 -> 3082.0053 | E28: =E26*E27 -> 2860.0165 | F28: =F26*F27 -> 2116.7663 | G28: =G26*G27 -> 2191.7205 | H28: =H26*H27 -> 2033.0001 | I28: =I26*I27 -> 1974.1757 | J28: =J26*J27 -> 2287.5227 | K28: =K26*K27 -> 2188.129 | ... P28: =P26*P27 -> 2194.4051 | R28: NPAT | T28: =SUM(T49,T71,T93,T115,T137) -> 19641310 | U28: =SUM(U49,U71,U93,U115,U137) -> 8588744.3 | V28: =SUM(V49,V71,V93,V115,V137) -> -16454804 | W28: =SUM(W49,W71,W93,W115,W137) -> -7814373.3 | X28: =SUM(X49,X71,X93,X115,X137) -> -14927964 | Y28: =SUM(Y49,Y71,Y93,Y115,Y137) -> -19192407 | Z28: =SUM(Z49,Z71,Z93,Z115,Z137) -> -1995255.5 | AA28: =SUM(AA49,AA71,AA93,AA115,AA137) -> 4540295.5 | ... AD28: =SUM(AD49,AD71,AD93,AD115,AD137) -> 7270548.1 | AE28: 14995095 | AF28: =SUM(T28:AE28) -> -50926259
B29: OCC | D29: =(D45*$E$33+D67*$E$55+D89*$E$77+D111*$E$99+D133*$E$121)/SUM($E$33,$E$55,$E$77,$E$99,$E$121) -> 0.8406497 | E29: =(E45*$E$33+E67*$E$55+E89*$E$77+E111*$E$99+E133*$E$121)/SUM($E$33,$E$55,$E$77,$E$99,$E$121) -> 0.82892743 | F29: =(F45*$E$33+F67*$E$55+F89*$E$77+F111*$E$99+F133*$E$121)/SUM($E$33,$E$55,$E$77,$E$99,$E$121) -> 0.66754043 | G29: =(G45*$E$33+G67*$E$55+G89*$E$77+G111*$E$99+G133*$E$121)/SUM($E$33,$E$55,$E$77,$E$99,$E$121) -> 0.66679565 | H29: =(H45*$E$33+H67*$E$55+H89*$E$77+H111*$E$99+H133*$E$121)/SUM($E$33,$E$55,$E$77,$E$99,$E$121) -> 0.68033289 | I29: =(I45*$E$33+I67*$E$55+I89*$E$77+I111*$E$99+I133*$E$121)/SUM($E$33,$E$55,$E$77,$E$99,$E$121) -> 0.66412383 | J29: =(J45*$E$33+J67*$E$55+J89*$E$77+J111*$E$99+J133*$E$121)/SUM($E$33,$E$55,$E$77,$E$99,$E$121) -> 0.7703775 | K29: =(K45*$E$33+K67*$E$55+K89*$E$77+K111*$E$99+K133*$E$121)/SUM($E$33,$E$55,$E$77,$E$99,$E$121) -> 0.79462901 | ... O29: =(O45*$E$33+O67*$E$55+O89*$E$77+O111*$E$99+O133*$E$121)/SUM($E$33,$E$55,$E$77,$E$99,$E$121) -> 0.82031761 | P29: =(D29*31+E29*28+F29*31+G29*30+H29*31+I29*30+J29*31+K29*31+L29*30+M29*31+N29*30+O29*31)/365 -> 0.74487611
B30: ADR | D30: =(D48*$E$33*D45+D70*$E$55*D67+$E$77*D89*D92+$E$99*D111*D114+$E$121*D133*D136)/SUM($E$33*D45,$E$55*D67,$E$77*D89,$E$99*D111,$E$121*D133) -> 3666.2182 | E30: =(E48*$E$33*E45+E70*$E$55*E67+$E$77*E89*E92+$E$99*E111*E114+$E$121*E133*E136)/SUM($E$33*E45,$E$55*E67,$E$77*E89,$E$99*E111,$E$121*E133) -> 3450.2617 | F30: =(F48*$E$33*F45+F70*$E$55*F67+$E$77*F89*F92+$E$99*F111*F114+$E$121*F133*F136)/SUM($E$33*F45,$E$55*F67,$E$77*F89,$E$99*F111,$E$121*F133) -> 3170.9934 | G30: =(G48*$E$33*G45+G70*$E$55*G67+$E$77*G89*G92+$E$99*G111*G114+$E$121*G133*G136)/SUM($E$33*G45,$E$55*G67,$E$77*G89,$E$99*G111,$E$121*G133) -> 3286.9449 | H30: =(H48*$E$33*H45+H70*$E$55*H67+$E$77*H89*H92+$E$99*H111*H114+$E$121*H133*H136)/SUM($E$33*H45,$E$55*H67,$E$77*H89,$E$99*H111,$E$121*H133) -> 2990.0159 | I30: =(I48*$E$33*I45+I70*$E$55*I67+$E$77*I89*I92+$E$99*I111*I114+$E$121*I133*I136)/SUM($E$33*I45,$E$55*I67,$E$77*I89,$E$99*I111,$E$121*I133) -> 2972.6018 | J30: =(J48*$E$33*J45+J70*$E$55*J67+$E$77*J89*J92+$E$99*J111*J114+$E$121*J133*J136)/SUM($E$33*J45,$E$55*J67,$E$77*J89,$E$99*J111,$E$121*J133) -> 3119.1504 | K30: =(K48*$E$33*K45+K70*$E$55*K67+$E$77*K89*K92+$E$99*K111*K114+$E$121*K133*K136)/SUM($E$33*K45,$E$55*K67,$E$77*K89,$E$99*K111,$E$121*K133) -> 3132.2813 | ... O30: =(O48*$E$33*O45+O70*$E$55*O67+$E$77*O89*O92+$E$99*O111*O114+$E$121*O133*O136)/SUM($E$33*O45,$E$55*O67,$E$77*O89,$E$99*O111,$E$121*O133) -> 3434.9158 | P30: =(D30*31+E30*28+F30*31+G30*30+H30*31+I30*30+J30*31+K30*31+L30*30+M30*31+N30*30+O30*31)/365 -> 3180.1886
B31: RevPar | D31: =D29*D30 -> 3082.0053 | E31: =E29*E30 -> 2860.0165 | F31: =F29*F30 -> 2116.7663 | G31: =G29*G30 -> 2191.7205 | H31: =H29*H30 -> 2034.2061 | I31: =I29*I30 -> 1974.1757 | J31: =J29*J30 -> 2402.9233 | K31: =K29*K30 -> 2489.0016 | ... P31: =P29*P30 -> 2368.8465 | AB31: =AB24-AB23 -> -666567.94 | AC31: =AC24-AC23 -> 15655186 | AF31: =AF23-AF24 -> -67799912
AB32: =AB27-AB26 -> -3.385 | AC32: =AC27-AC26 -> -3.39 | AF32: =AF27-AF26 -> 6787487.4
E33: 445 | P33: SR9 | R33: kthb
B34: SR9 | D34: 2025 | P34: Avg | R34: SR9 | T34: 2025 | AF34: Total | AH34: =SUM(AF36,AF58,AF80,AF102,AF124) -> 1.6415156e+09
D35: Jan | E35: Feb | F35: Mar | G35: Apr | H35: May | I35: Jun | J35: Jul | K35: Aug | L35: Sep | M35: Oct | N35: Nov | O35: Dec | T35: Jan | U35: Feb | V35: Mar | W35: Apr | X35: May | Y35: Jun | Z35: Jul | AA35: Aug | AB35: Sep | AC35: Oct | AD35: Nov | AE35: Dec | AH35: =AF24 -> 8.9992375e+08 | AI35: =AH35/AH34 -> 0.54822734
B36: Ascott BP | R36: Total Revenue | T36: 40471407 | U36: 35097386 | V36: 31885906 | W36: 28944482 | X36: 29907879 | Y36: 28869836 | Z36: 36038410 | AA36: 33833375 | AB36: 25832653 | AC36: 28644008 | AD36: 35706457 | AE36: 39293092 | AF36: =SUM(T36:AE36) -> 3.9452489e+08 | AH36: =AF27 -> 3.7277348e+08 | AI36: =AH36/AH34 -> 0.22709104
B37: OCC | D37: 0.90004112 | E37: 0.89 | F37: 0.86005213 | G37: 0.85449438 | H37: 0.86995288 | I37: 0.83042487 | J37: 0.90661213 | K37: 0.90993618 | L37: 0.67715356 | M37: 0.71547662 | N37: 0.86067416 | O37: 0.85770207 | P37: =(D37*31+E37*28+F37*31+G37*30+H37*31+I37*30+J37*31+K37*31+L37*30+M37*31+N37*30+O37*31)/365 -> 0.84442569 | R37: Ascott BP OPEX | T37: -17324064 | U37: -16257642 | V37: -16841922 | W37: -16999978 | X37: -17369705 | Y37: -16719378 | Z37: -16600895 | AA37: -17143570 | AB37: -16116868 | AC37: -16436879 | AD37: -16837325 | AE37: -17066591 | AF37: =SUM(T37:AE37) -> -2.0171482e+08
B38: ADR | D38: 3359.8465 | E38: 3390 | F38: 3349.797 | G38: 3380 | H38: 3320 | I38: 3304.9999 | J38: 3350.195 | K38: 3380.237 | L38: 2668 | M38: 2731 | N38: 2879 | O38: 3111 | P38: =(D38*31+E38*28+F38*31+G38*30+H38*31+I38*30+J38*31+K38*31+L38*30+M38*31+N38*30+O38*31)/365 -> 3185.053 | R38: MF Projection OPEX | T38: -16229518 | U38: -14927114 | V38: -13795448 | W38: -12830962 | X38: -13004015 | Y38: -12975051 | Z38: -14326344 | AA38: -13446375 | AB38: -9533685.2 | AC38: -9848834.7 | AD38: -13148126 | AE38: -14858277 | AF38: =SUM(T38:AE38) -> -1.5892375e+08
B39: RevPar | D39: =D37*D38 -> 3024 | E39: =E37*E38 -> 3017.1 | F39: =F37*F38 -> 2881 | G39: =G37*G38 -> 2888.191 | H39: =H37*H38 -> 2888.2436 | I39: =I37*I38 -> 2744.5541 | J39: =J37*J38 -> 3037.3275 | K39: =K37*K38 -> 3075.7999 | L39: 1806.6457 | M39: 1953.9667 | N39: 2477.8809 | O39: 2668.3111 | P39: =P37*P38 -> 2689.5406 | R39: OPEX | T39: -16229518 | U39: -14927114 | V39: -13795448 | W39: -12830962 | X39: -13004015 | Y39: -12975051 | Z39: -15032009 | AA39: -14366759 | AB39: -12105413 | AC39: -13283033 | AD39: -14449194 | AE39: -15442482 | AF39: =SUM(T39:AE39) -> -1.68441e+08
B40: MF Projection | R40: Ascott BP GOP | T40: 26263980 | U40: 23040152 | V40: 24706189 | W40: 23303141 | X40: 24295956 | Y40: 21626484 | Z40: 27188599 | AA40: 27182567 | AB40: 20112140 | AC40: 21209590 | AD40: 24239585 | AE40: 24355335 | AF40: =SUM(T40:AE40) -> 2.8752372e+08
B41: OCC | D41: 0.84682856 | E41: 0.87736758 | F41: 0.75208409 | G41: 0.6705618 | H41: 0.74889453 | I41: 0.73625468 | J41: 0.80820216 | K41: 0.75612342 | L41: 0.64810579 | M41: 0.64810579 | N41: 0.75612342 | O41: 0.7921293 | P41: =(D41*31+E41*28+F41*31+G41*30+H41*31+I41*30+J41*31+K41*31+L41*30+M41*31+N41*30+O41*31)/365 -> 0.75293443 | R41: MF Projection GOP | T41: 24241888 | U41: 20170272 | V41: 18090458 | W41: 16113520 | X41: 16903865 | Y41: 15894785 | Z41: 19592430 | AA41: 18249123 | AB41: 13244214 | AC41: 13677767 | AD41: 18066955 | AE41: 20330928 | AF41: =SUM(T41:AE41) -> 2.1457621e+08
B42: ADR | D42: 3342.4448 | E42: 3059.3151 | F42: 2930.9572 | G42: 3005.1264 | H42: 2764.293 | I42: 2778.2919 | J42: 2805.5548 | K42: 2832.5313 | L42: 2373.931 | M42: 2373.931 | N42: 2832.5313 | O42: 2967.4137 | P42: =(D42*31+E42*28+F42*31+G42*30+H42*31+I42*30+J42*31+K42*31+L42*30+M42*31+N42*30+O42*31)/365 -> 2838.0497 | R42: GOP | T42: =T36+T39 -> 24241888 | U42: =U36+U39 -> 20170272 | V42: =V36+V39 -> 18090458 | W42: =W36+W39 -> 16113520 | X42: =X36+X39 -> 16903865 | Y42: =Y36+Y39 -> 15894785 | Z42: =Z36+Z39 -> 21006401 | AA42: =AA36+AA39 -> 19466616 | ... AD42: =AD36+AD39 -> 21257263 | AE42: 23850610 | AF42: =AF36+AF39 -> 2.2608389e+08 | AG42: fall below
B43: RevPar | D43: =D41*D42 -> 2830.4777 | E43: =E41*E42 -> 2684.1438 | F43: =F41*F42 -> 2204.3263 | G43: =G41*G42 -> 2015.123 | H43: =H41*H42 -> 2070.1639 | I43: =I41*I42 -> 2045.5304 | J43: =J41*J42 -> 2267.4554 | K43: =K41*K42 -> 2141.7432 | L43: 1538.5584 | M43: 1538.5584 | N43: 2141.7432 | O43: 2350.5753 | P43: =P41*P42 -> 2136.8653 | R43: Ascott BP % GOP | T43: 0.60255009 | U43: 0.58629632 | V43: 0.5946405 | W43: 0.57819696 | X43: 0.58311702 | Y43: 0.56398482 | Z43: 0.6208932 | AA43: 0.61324015 | AB43: 0.55513913 | AC43: 0.56338856 | AD43: 0.59010245 | AE43: 0.58798171 | AF43: =AVERAGE(T43:AE43) -> 0.58662758
B44: Actual Result | R44: MF Projection % GOP | T44: 0.59898803 | U44: 0.57469443 | V44: 0.56734967 | W44: 0.55670437 | X44: 0.56519771 | Y44: 0.55056719 | Z44: 0.56308392 | AA44: 0.56308392 | AB44: 0.56308392 | AC44: 0.56308392 | AD44: 0.56308392 | AE44: 0.56308392 | AF44: =AVERAGE(T44:AE44) -> 0.56600041
B45: OCC | D45: ='[275]LSSS FY25'!C5 -> 0.84682856 | E45: ='[275]LSSS FY25'!D5 -> 0.87736758 | F45: ='[275]LSSS FY25'!E5 -> 0.75208409 | G45: ='[275]LSSS FY25'!F5 -> 0.6705618 | H45: ='[275]LSSS FY25'!G5 -> 0.74889453 | I45: ='[275]LSSS FY25'!H5 -> 0.73625468 | J45: ='[275]LSSS FY25'!I5 -> 0.84835085 | K45: ='[275]LSSS FY25'!J5 -> 0.80188474 | ... N45: ='[275]LSSS FY25'!M5 -> 0.86067416 | O45: 0.85770207 | P45: =(D45*31+E45*28+F45*31+G45*30+H45*31+I45*30+J45*31+K45*31+L45*30+M45*31+N45*30+O45*31)/365 -> 0.78250269 | R45: % GOP Margin | T45: =T42/T36 -> 0.59898803 | U45: =U42/U36 -> 0.57469443 | V45: =V42/V36 -> 0.56734967 | W45: =W42/W36 -> 0.55670437 | X45: =X42/X36 -> 0.56519771 | Y45: =Y42/Y36 -> 0.55056719 | Z45: =Z42/Z36 -> 0.58288923 | AA45: =AA42/AA36 -> 0.57536724 | ... AD45: =AD42/AD36 -> 0.59533387 | AE45: 0.60699245 | AF45: =AF42/AF36 -> 0.57305356
C46: LS | D46: ='[275]LSSS FY25'!C29 -> 0.14628489 | E46: ='[275]LSSS FY25'!D29 -> 0.10064205 | F46: ='[275]LSSS FY25'!E29 -> 0.078144255 | G46: ='[275]LSSS FY25'!F29 -> 0.085992509 | H46: ='[275]LSSS FY25'!G29 -> 0.13040957 | I46: ='[275]LSSS FY25'!H29 -> 0.1447191 | J46: ='[275]LSSS FY25'!I29 -> 0.10945995 | K46: ='[275]LSSS FY25'!J29 -> 0.095614353 | ... N46: ='[275]LSSS FY25'!M29 -> 0.093782772 | O46: 0.08851033 | P46: =(D46*31+E46*28+F46*31+G46*30+H46*31+I46*30+J46*31+K46*31+L46*30+M46*31+N46*30+O46*31)/365 -> 0.10244113 | R46: Ascott BP EBIT | T46: 15585082 | U46: 12636032 | V46: 14158999 | W46: 12859024 | X46: 13767477 | Y46: 11324323 | Z46: 16458783 | AA46: 16441117 | AB46: 9941860.1 | AC46: 10948719 | AD46: 13733159 | AE46: 13834297 | AF46: =SUM(T46:AE46) -> 1.6168887e+08
...

Sheet result FY26
C3: YTD performance | F3: Jun
C4: Unit: kTHB
C5: SR9 | D5: Compare with MF Projection | I5: AES | J5: Compare with MF Projection | O5: lyf | P5: Compare with MF Projection | U5: SP | V5: Compare with MF Projection | AA5: Portfolio | AB5: Compare with MF Projection
D6: Ascott BP | E6: MF Projection | F6: Actual | G6: % change | J6: Ascott BP | K6: MF Projection | L6: Actual | M6: % change | P6: Ascott BP | Q6: MF Projection | R6: Actual | S6: % change | V6: Ascott BP | W6: MF Projection | X6: Actual | Y6: % change | AB6: Ascott BP | AC6: MF Projection | AD6: Actual | AE6: % change
C7: OCC | D7: {=SUMPRODUCT(D37:_xlfn.XLOOKUP($F$3,$D$21:$O$21,D37:O37),$D$19:_xlfn.XLOOKUP($F$3,$D$21:$O$21,$D$19:$O$19)/SUM($D$19:_xlfn.XLOOKUP($F$3,$D$21:$O$21,$D$19:$O$19)))} -> 0.80100999 | E7: {=SUMPRODUCT(D41:_xlfn.XLOOKUP($F$3,$D$21:$O$21,D41:O41),$D$19:_xlfn.XLOOKUP($F$3,$D$21:$O$21,$D$19:$O$19)/SUM($D$19:_xlfn.XLOOKUP($F$3,$D$21:$O$21,$D$19:$O$19)))} -> 0.80100999 | F7: {=SUMPRODUCT(D45:_xlfn.XLOOKUP($F$3,$D$21:$O$21,D45:O45),$D$19:_xlfn.XLOOKUP($F$3,$D$21:$O$21,$D$19:$O$19)/SUM($D$19:_xlfn.XLOOKUP($F$3,$D$21:$O$21,$D$19:$O$19)))} -> 0.80800795 | G7: =(F7-E7)/E7 -> 0.0087364097 | I7: OCC | J7: {=SUMPRODUCT(D60:_xlfn.XLOOKUP($F$3,$D$21:$O$21,D60:O60),$D$19:_xlfn.XLOOKUP($F$3,$D$21:$O$21,$D$19:$O$19)/SUM($D$19:_xlfn.XLOOKUP($F$3,$D$21:$O$21,$D$19:$O$19)))} -> 0.71707182 | K7: {=SUMPRODUCT(D64:_xlfn.XLOOKUP($F$3,$D$21:$O$21,D64:O64),$D$19:_xlfn.XLOOKUP($F$3,$D$21:$O$21,$D$19:$O$19)/SUM($D$19:_xlfn.XLOOKUP($F$3,$D$21:$O$21,$D$19:$O$19)))} -> 0.71601085 | L7: {=SUMPRODUCT(D68:_xlfn.XLOOKUP($F$3,$D$21:$O$21,D68:O68),$D$19:_xlfn.XLOOKUP($F$3,$D$21:$O$21,$D$19:$O$19)/SUM($D$19:_xlfn.XLOOKUP($F$3,$D$21:$O$21,$D$19:$O$19)))} -> 0.70444098 | M7: =(L7-K7)/K7 -> -0.0161588 | O7: OCC | P7: {=SUMPRODUCT(D83:_xlfn.XLOOKUP($F$3,$D$21:$O$21,D83:O83),$D$19:_xlfn.XLOOKUP($F$3,$D$21:$O$21,$D$19:$O$19)/SUM($D$19:_xlfn.XLOOKUP($F$3,$D$21:$O$21,$D$19:$O$19)))} -> 0.82641786 | Q7: {=SUMPRODUCT(D87:_xlfn.XLOOKUP($F$3,$D$21:$O$21,D87:O87),$D$19:_xlfn.XLOOKUP($F$3,$D$21:$O$21,$D$19:$O$19)/SUM($D$19:_xlfn.XLOOKUP($F$3,$D$21:$O$21,$D$19:$O$19)))} -> 0.82641786 | R7: {=SUMPRODUCT(D91:_xlfn.XLOOKUP($F$3,$D$21:$O$21,D91:O91),$D$19:_xlfn.XLOOKUP($F$3,$D$21:$O$21,$D$19:$O$19)/SUM($D$19:_xlfn.XLOOKUP($F$3,$D$21:$O$21,$D$19:$O$19)))} -> 0.78083775 | S7: =(R7-Q7)/Q7 -> -0.05515383 | U7: OCC | V7: {=SUMPRODUCT(D106:_xlfn.XLOOKUP($F$3,$D$21:$O$21,D106:O106),$D$19:_xlfn.XLOOKUP($F$3,$D$21:$O$21,$D$19:$O$19)/SUM($D$19:_xlfn.XLOOKUP($F$3,$D$21:$O$21,$D$19:$O$19)))} -> 0.74839779 | W7: {=SUMPRODUCT(D110:_xlfn.XLOOKUP($F$3,$D$21:$O$21,D110:O110),$D$19:_xlfn.XLOOKUP($F$3,$D$21:$O$21,$D$19:$O$19)/SUM($D$19:_xlfn.XLOOKUP($F$3,$D$21:$O$21,$D$19:$O$19)))} -> 0.73635837 | X7: {=SUMPRODUCT(D114:_xlfn.XLOOKUP($F$3,$D$21:$O$21,D114:O114),$D$19:_xlfn.XLOOKUP($F$3,$D$21:$O$21,$D$19:$O$19)/SUM($D$19:_xlfn.XLOOKUP($F$3,$D$21:$O$21,$D$19:$O$19)))} -> 0.73789305 | Y7: =(X7-W7)/W7 -> 0.0020841535 | AA7: OCC | AB7: {=SUMPRODUCT(D23:_xlfn.XLOOKUP($F$3,$D$21:$O$21,D23:O23),$D$19:_xlfn.XLOOKUP($F$3,$D$21:$O$21,$D$19:$O$19)/SUM($D$19:_xlfn.XLOOKUP($F$3,$D$21:$O$21,$D$19:$O$19)))} -> 0.76783318 | AC7: {=SUMPRODUCT(D26:_xlfn.XLOOKUP($F$3,$D$21:$O$21,D26:O26),$D$19:_xlfn.XLOOKUP($F$3,$D$21:$O$21,$D$19:$O$19)/SUM($D$19:_xlfn.XLOOKUP($F$3,$D$21:$O$21,$D$19:$O$19)))} -> 0.7646537 | AD7: {=SUMPRODUCT(D29:_xlfn.XLOOKUP($F$3,$D$21:$O$21,D29:O29),$D$19:_xlfn.XLOOKUP($F$3,$D$21:$O$21,$D$19:$O$19)/SUM($D$19:_xlfn.XLOOKUP($F$3,$D$21:$O$21,$D$19:$O$19)))} -> 0.75738615 | AE7: =(AD7-AC7)/AC7 -> -0.0095043718
C8: ADR | D8: {=SUMPRODUCT(D38:_xlfn.XLOOKUP($F$3,$D$21:$O$21,D38:O38),$D$19:_xlfn.XLOOKUP($F$3,$D$21:$O$21,$D$19:$O$19)/SUM($D$19:_xlfn.XLOOKUP($F$3,$D$21:$O$21,$D$19:$O$19)))} -> 2948.5504 | E8: {=SUMPRODUCT(D42:_xlfn.XLOOKUP($F$3,$D$21:$O$21,D42:O42),$D$19:_xlfn.XLOOKUP($F$3,$D$21:$O$21,$D$19:$O$19)/SUM($D$19:_xlfn.XLOOKUP($F$3,$D$21:$O$21,$D$19:$O$19)))} -> 2948.5504 | F8: {=SUMPRODUCT(D48:_xlfn.XLOOKUP($F$3,$D$21:$O$21,D48:O48),$D$19:_xlfn.XLOOKUP($F$3,$D$21:$O$21,$D$19:$O$19)/SUM($D$19:_xlfn.XLOOKUP($F$3,$D$21:$O$21,$D$19:$O$19)))} -> 2709.3088 | G8: =(F8-E8)/E8 -> -0.081138699 | I8: ADR | J8: {=SUMPRODUCT(D61:_xlfn.XLOOKUP($F$3,$D$21:$O$21,D61:O61),$D$19:_xlfn.XLOOKUP($F$3,$D$21:$O$21,$D$19:$O$19)/SUM($D$19:_xlfn.XLOOKUP($F$3,$D$21:$O$21,$D$19:$O$19)))} -> 3633.0588 | K8: {=SUMPRODUCT(D65:_xlfn.XLOOKUP($F$3,$D$21:$O$21,D65:O65),$D$19:_xlfn.XLOOKUP($F$3,$D$21:$O$21,$D$19:$O$19)/SUM($D$19:_xlfn.XLOOKUP($F$3,$D$21:$O$21,$D$19:$O$19)))} -> 3633.0588 | L8: {=SUMPRODUCT(D71:_xlfn.XLOOKUP($F$3,$D$21:$O$21,D71:O71),$D$19:_xlfn.XLOOKUP($F$3,$D$21:$O$21,$D$19:$O$19)/SUM($D$19:_xlfn.XLOOKUP($F$3,$D$21:$O$21,$D$19:$O$19)))} -> 3302.9306 | M8: =(L8-K8)/K8 -> -0.09086782 | O8: ADR | P8: {=SUMPRODUCT(D84:_xlfn.XLOOKUP($F$3,$D$21:$O$21,D84:O84),$D$19:_xlfn.XLOOKUP($F$3,$D$21:$O$21,$D$19:$O$19)/SUM($D$19:_xlfn.XLOOKUP($F$3,$D$21:$O$21,$D$19:$O$19)))} -> 1498.8101 | Q8: {=SUMPRODUCT(D88:_xlfn.XLOOKUP($F$3,$D$21:$O$21,D88:O88),$D$19:_xlfn.XLOOKUP($F$3,$D$21:$O$21,$D$19:$O$19)/SUM($D$19:_xlfn.XLOOKUP($F$3,$D$21:$O$21,$D$19:$O$19)))} -> 1476.6602 | R8: {=SUMPRODUCT(D94:_xlfn.XLOOKUP($F$3,$D$21:$O$21,D94:O94),$D$19:_xlfn.XLOOKUP($F$3,$D$21:$O$21,$D$19:$O$19)/SUM($D$19:_xlfn.XLOOKUP($F$3,$D$21:$O$21,$D$19:$O$19)))} -> 1360.3017 | S8: =(R8-Q8)/Q8 -> -0.078798408 | U8: ADR | V8: {=SUMPRODUCT(D107:_xlfn.XLOOKUP($F$3,$D$21:$O$21,D107:O107),$D$19:_xlfn.XLOOKUP($F$3,$D$21:$O$21,$D$19:$O$19)/SUM($D$19:_xlfn.XLOOKUP($F$3,$D$21:$O$21,$D$19:$O$19)))} -> 3859.9481 | W8: {=SUMPRODUCT(D111:_xlfn.XLOOKUP($F$3,$D$21:$O$21,D111:O111),$D$19:_xlfn.XLOOKUP($F$3,$D$21:$O$21,$D$19:$O$19)/SUM($D$19:_xlfn.XLOOKUP($F$3,$D$21:$O$21,$D$19:$O$19)))} -> 3856.0269 | X8: {=SUMPRODUCT(D117:_xlfn.XLOOKUP($F$3,$D$21:$O$21,D117:O117),$D$19:_xlfn.XLOOKUP($F$3,$D$21:$O$21,$D$19:$O$19)/SUM($D$19:_xlfn.XLOOKUP($F$3,$D$21:$O$21,$D$19:$O$19)))} -> 3512.1778 | Y8: =(X8-W8)/W8 -> -0.089171863 | AA8: ADR | AB8: {=SUMPRODUCT(D24:_xlfn.XLOOKUP($F$3,$D$21:$O$21,D24:O24),$D$19:_xlfn.XLOOKUP($F$3,$D$21:$O$21,$D$19:$O$19)/SUM($D$19:_xlfn.XLOOKUP($F$3,$D$21:$O$21,$D$19:$O$19)))} -> 3120.5896 | AC8: {=SUMPRODUCT(D27:_xlfn.XLOOKUP($F$3,$D$21:$O$21,D27:O27),$D$19:_xlfn.XLOOKUP($F$3,$D$21:$O$21,$D$19:$O$19)/SUM($D$19:_xlfn.XLOOKUP($F$3,$D$21:$O$21,$D$19:$O$19)))} -> 3113.4673 | AD8: {=SUMPRODUCT(D30:_xlfn.XLOOKUP($F$3,$D$21:$O$21,D30:O30),$D$19:_xlfn.XLOOKUP($F$3,$D$21:$O$21,$D$19:$O$19)/SUM($D$19:_xlfn.XLOOKUP($F$3,$D$21:$O$21,$D$19:$O$19)))} -> 2855.2308 | AE8: =(AD8-AC8)/AC8 -> -0.082941755 | AF8: YTD still lower than BG
C9: RevPar | D9: =D7*D8 -> 2361.8183 | E9: =E7*E8 -> 2361.8183 | F9: =F7*F8 -> 2189.143 | G9: =(F9-E9)/E9 -> -0.07311115 | I9: RevPar | J9: =J7*J8 -> 2605.1641 | K9: =K7*K8 -> 2601.3095 | L9: =L7*L8 -> 2326.7197 | M9: =(L9-K9)/K9 -> -0.1055583 | O9: RevPar | P9: =P7*P8 -> 1238.6434 | Q9: =Q7*Q8 -> 1220.3383 | R9: =R7*R8 -> 1062.1749 | S9: =(R9-Q9)/Q9 -> -0.1296062 | U9: RevPar | V9: =V7*V8 -> 2888.7766 | W9: =W7*W8 -> 2839.4177 | X9: =X7*X8 -> 2591.6116 | Y9: =(X9-W9)/W9 -> -0.087273557 | AA9: RevPar | AB9: =AB7*AB8 -> 2396.0922 | AC9: =AC7*AC8 -> 2380.7243 | AD9: =AD7*AD8 -> 2162.5123 | AE9: =(AD9-AC9)/AC9 -> -0.091657817
C10: GOP Margin | D10: =D14/D12 -> 0.57735728 | E10: =E14/E12 -> 0.56853481 | F10: =F14/F12 -> 0.57068731 | G10: =(F10-E10)/E10 -> 0.0037860519 | I10: GOP Margin | J10: =J14/J12 -> 0.52528254 | K10: =K14/K12 -> 0.5135675 | L10: =L14/L12 -> 0.5333681 | M10: =(L10-K10)/K10 -> 0.03855502 | O10: GOP Margin | P10: =P14/P12 -> 0.48843871 | Q10: =Q14/Q12 -> 0.48087657 | R10: =R14/R12 -> 0.45882112 | S10: =(R10-Q10)/Q10 -> -0.045865095 | U10: GOP Margin | V10: =V14/V12 -> 0.55534309 | W10: =W14/W12 -> 0.54979811 | X10: =X14/X12 -> 0.55324024 | Y10: =(X10-W10)/W10 -> 0.0062607202 | AA10: GOP Margin | AB10: =AB14/AB12 -> 0.54843882 | AC10: =AC14/AC12 -> 0.53988971 | AD10: =AD14/AD12 -> 0.54652062 | AE10: =(AD10-AC10)/AC10 -> 0.012281982
C12: Revenue | D12: =D14-D13 -> 2.1396618e+08 | E12: =E14-E13 -> 2.1396618e+08 | F12: =SUM(T36:AE36) -> 1.9627854e+08 | G12: =(F12-E12)/E12 -> -0.08266559 | I12: Revenue | J12: =J14-J13 -> 2.0401754e+08 | K12: =K14-K13 -> 2.0401754e+08 | L12: =SUM(T59:AE59) -> 1.7923401e+08 | M12: =(L12-K12)/K12 -> -0.12147746 | O12: Revenue | P12: =P14-P13 -> 45752307 | Q12: =Q14-Q13 -> 43602725 | R12: =SUM(T82:AE82) -> 39959053 | S12: =(R12-Q12)/Q12 -> -0.083565231 | U12: Revenue | V12: =V14-V13 -> 1.8566169e+08 | W12: =W14-W13 -> 1.8310152e+08 | X12: =SUM(T105:AE105) -> 1.6643298e+08 | Y12: =(X12-W12)/W12 -> -0.091034434 | AA12: Revenue | AB12: =SUM(D12,J12,P12,V12) -> 6.4939772e+08 | AC12: =SUM(E12,,K12,Q12,W12) -> 6.4468797e+08 | AD12: =SUM(F12,L12,R12,X12) -> 5.8190458e+08 | AE12: =(AD12-AC12)/AC12 -> -0.0973857 | AH12: =AF36+AF59+AF82+AF105 -> 5.8190458e+08
C13: OPEX | D13: =SUM(OFFSET($T37, 0, 0, 1, MATCH($F$3, $T$35:$AE$35, 0))) -> -90431249 | E13: =SUM(OFFSET($T38, 0, 0, 1, MATCH($F$3, $T$35:$AE$35, 0))) -> -92318958 | F13: =SUM(T39:AE39) -> -84264867 | G13: =(F13-E13)/E13 -> -0.087242007 | I13: OPEX | J13: =SUM(OFFSET($T60, 0, 0, 1, MATCH($F$3, $T$58:$AE$58, 0))) -> -96850691 | K13: =SUM(OFFSET($T61, 0, 0, 1, MATCH($F$3, $T$58:$AE$58, 0))) -> -99240765 | L13: =SUM(T62:AE62) -> -83636307 | M13: =(L13-K13)/K13 -> -0.15723839 | O13: OPEX | P13: =SUM(OFFSET($T83, 0, 0, 1, MATCH($F$3, $T$81:$AE$81, 0))) -> -23405109 | Q13: =SUM(OFFSET($T84, 0, 0, 1, MATCH($F$3, $T$81:$AE$81, 0))) -> -22635196 | R13: =SUM(T85:AE85) -> -21624996 | S13: =(R13-Q13)/Q13 -> -0.044629633 | U13: OPEX | V13: =SUM(OFFSET($T106, 0, 0, 1, MATCH($F$3, $T$104:$AE$104, 0))) -> -82555754 | W13: =SUM(OFFSET($T107, 0, 0, 1, MATCH($F$3, $T$104:$AE$104, 0))) -> -82432651 | X13: =SUM(T108:AE108) -> -74355557 | Y13: =(X13-W13)/W13 -> -0.097984159 | AA13: OPEX | AB13: =SUM(D13,J13,P13,V13) -> -2.932428e+08 | AC13: =SUM(E13,,K13,Q13,W13) -> -2.9662757e+08 | AD13: =SUM(F13,L13,R13,X13) -> -2.6388173e+08 | AE13: =(AD13-AC13)/AC13 -> -0.1103938 | AH13: =AF39+AF62+AF85+AF108 -> -2.6388173e+08
C14: GOP | D14: =SUM(OFFSET($T40, 0, 0, 1, MATCH($F$3, $T$35:$AE$35, 0))) -> 1.2353493e+08 | E14: =SUM(OFFSET($T41, 0, 0, 1, MATCH($F$3, $T$35:$AE$35, 0))) -> 1.2164722e+08 | F14: =F12+F13 -> 1.1201367e+08 | G14: =(F14-E14)/E14 -> -0.079192514 | I14: GOP | J14: =SUM(OFFSET($T63, 0, 0, 1, MATCH($F$3, $T$58:$AE$58, 0))) -> 1.0716685e+08 | K14: =SUM(OFFSET($T64, 0, 0, 1, MATCH($F$3, $T$58:$AE$58, 0))) -> 1.0477678e+08 | L14: =L12+L13 -> 95597704 | M14: =(L14-K14)/K14 -> -0.087606007 | O14: GOP | P14: =SUM(OFFSET($T86, 0, 0, 1, MATCH($F$3, $T$81:$AE$81, 0))) -> 22347198 | Q14: =SUM(OFFSET($T87, 0, 0, 1, MATCH($F$3, $T$81:$AE$81, 0))) -> 20967529 | R14: =R12+R13 -> 18334057 | S14: =(R14-Q14)/Q14 -> -0.1255976 | U14: GOP | V14: =SUM(OFFSET($T109, 0, 0, 1, MATCH($F$3, $T$104:$AE$104, 0))) -> 1.0310594e+08 | W14: =SUM(OFFSET($T110, 0, 0, 1, MATCH($F$3, $T$104:$AE$104, 0))) -> 1.0066887e+08 | X14: =X12+X13 -> 92077420 | Y14: =(X14-W14)/W14 -> -0.085343655 | AA14: GOP | AB14: =SUM(D14,J14,P14,V14) -> 3.5615492e+08 | AC14: =SUM(E14,,K14,Q14,W14) -> 3.480604e+08 | AD14: =SUM(F14,L14,R14,X14) -> 3.1802285e+08 | AE14: =(AD14-AC14)/AC14 -> -0.086299807
C15: JV expense | D15: =D16-D14 -> -44116320 | E15: =E16-E14 -> -61905238 | F15: =F16-F14 -> -59010430 | G15: =(F15-E15)/E15 -> -0.046761921 | I15: JV expense | J15: =J16-J14 -> -53265404 | K15: =K16-K14 -> -69690642 | L15: =L16-L14 -> -62082625 | M15: =(L15-K15)/K15 -> -0.10916843 | O15: JV expense | P15: =P16-P14 -> -15350520 | Q15: =Q16-Q14 -> -13970851 | R15: =R16-R14 -> -13788209 | S15: =(R15-Q15)/Q15 -> -0.013073059 | U15: JV expense | V15: =V16-V14 -> -10519785 | W15: =W16-W14 -> -41567488 | X15: =X16-X14 -> -39893137 | Y15: =(X15-W15)/W15 -> -0.040280323 | AA15: JV expense | AB15: =SUM(D15,J15,P15,V15) -> -1.2325203e+08 | AC15: =SUM(E15,K15,Q15,W15) -> -1.8713422e+08 | AD15: =SUM(F15,L15,R15,X15) -> -1.747744e+08 | AE15: =(AD15-AC15)/AC15 -> -0.066047884
C16: EBIT | D16: =SUM(OFFSET($T46, 0, 0, 1, MATCH($F$3, $T$35:$AE$35, 0))) -> 79418611 | E16: =SUM(OFFSET($T47, 0, 0, 1, MATCH($F$3, $T$35:$AE$35, 0))) -> 59741984 | F16: =SUM(T48:AE48) -> 53003242 | G16: =(F16-E16)/E16 -> -0.11279742 | I16: EBIT | J16: =SUM(OFFSET($T69, 0, 0, 1, MATCH($F$3, $T$58:$AE$58, 0))) -> 53901450 | K16: =SUM(OFFSET($T70, 0, 0, 1, MATCH($F$3, $T$58:$AE$58, 0))) -> 35086137 | L16: =SUM(T71:AE71) -> 33515079 | M16: =(L16-K16)/K16 -> -0.044777162 | O16: EBIT | P16: =SUM(OFFSET($T93, 0, 0, 1, MATCH($F$3, $T$81:$AE$81, 0))) -> 6996677.8 | Q16: =SUM(OFFSET($T93, 0, 0, 1, MATCH($F$3, $T$81:$AE$81, 0))) -> 6996677.8 | R16: =SUM(T94:AE94) -> 4545848.3 | S16: =(R16-Q16)/Q16 -> -0.35028474 | U16: EBIT | V16: =SUM(OFFSET($T115, 0, 0, 1, MATCH($F$3, $T$104:$AE$104, 0))) -> 92586154 | W16: =SUM(OFFSET($T116, 0, 0, 1, MATCH($F$3, $T$104:$AE$104, 0))) -> 59101381 | X16: =SUM(T117:AE117) -> 52184283 | Y16: =(X16-W16)/W16 -> -0.11703783 | AA16: EBIT | AB16: =SUM(D16,J16,P16,V16) -> 2.3290289e+08 | AC16: =SUM(E16,K16,Q16,W16) -> 1.6092618e+08 | AD16: =SUM(F16,L16,R16,X16) -> 1.4324845e+08 | AE16: =(AD16-AC16)/AC16 -> -0.10984991
D19: 31 | E19: 28 | F19: 31 | G19: 30 | H19: 31 | I19: 30 | J19: 31 | K19: 31 | L19: 30 | M19: 31 | N19: 30 | O19: 31 | P19: =SUM(D19:O19) -> 365
B20: Portfolio | D20: 2026 | P20: Avg | R20: Overall GOP / EBIT | T20: 2026 | AF20: Total
D21: Jan | E21: Feb | F21: Mar | G21: Apr | H21: May | I21: Jun | J21: Jul | K21: Aug | L21: Sep | M21: Oct | N21: Nov | O21: Dec | T21: Jan | U21: Feb | V21: Mar | W21: Apr | X21: May | Y21: Jun | Z21: Jul | AA21: Aug | AB21: Sep | AC21: Oct | AD21: Nov | AE21: Dec
B22: Key Available | D22: =E33+E56+E79+E102 -> 1358 | E22: =D22 -> 1358 | F22: =E22 -> 1358 | G22: =F22 -> 1358 | H22: =G22 -> 1358 | I22: =H22 -> 1358 | J22: =I22 -> 1358 | K22: =J22 -> 1358 | L22: =K22 -> 1358 | ... O22: =N22 -> 1358 | R22: Total Revenue | T22: =SUM(T36,T59,T82,T105) -> 1.1844209e+08 | U22: =SUM(U36,U59,U82,U105) -> 1.1670003e+08 | V22: =SUM(V36,V59,V82,V105) -> 99275487 | W22: =SUM(W36,W59,W82,W105) -> 88366637 | X22: =SUM(X36,X59,X82,X105) -> 80532065 | Y22: =SUM(Y36,Y59,Y82,Y105) -> 78588277 | AF22: =SUM(T22:AE22) -> 5.8190458e+08
B23: Ascott BP OCC | D23: =(D37*$E$33+D60*$E$56+D83*$E$79+D106*$E$102)/SUM($E$33,$E$56,$E$79,$E$102) -> 0.83438097 | E23: =(E37*$E$33+E60*$E$56+E83*$E$79+E106*$E$102)/SUM($E$33,$E$56,$E$79,$E$102) -> 0.87066274 | F23: =(F37*$E$33 +F60*$E$56+F83*$E$79+F106*$E$102)/SUM($E$33,$E$56,$E$79,$E$102) -> 0.71845978 | G23: =(G37*$E$33 +G60*$E$56+G83*$E$79+G106*$E$102)/SUM($E$33,$E$56,$E$79,$E$102) -> 0.75059156 | H23: =(H37*$E$33 +H60*$E$56+H83*$E$79+H106*$E$102)/SUM($E$33,$E$56,$E$79,$E$102) -> 0.72668749 | I23: =(I37*$E$33 +I60*$E$56+I83*$E$79+I106*$E$102)/SUM($E$33,$E$56,$E$79,$E$102) -> 0.71387089 | J23: =(J37*$E$33 +J60*$E$56+J83*$E$79+J106*$E$102)/SUM($E$33,$E$56,$E$79,$E$102) -> 0.79627702 | K23: =(K37*$E$33 +K60*$E$56+K83*$E$79+K106*$E$102)/SUM($E$33,$E$56,$E$79,$E$102) -> 0.80044325 | L23: =(L37*$E$33 +L60*$E$56+L83*$E$79+L106*$E$102)/SUM($E$33,$E$56,$E$79,$E$102) -> 0.72295042 | M23: =(M37*$E$33 +M60*$E$56+M83*$E$79+M106*$E$102)/SUM($E$33,$E$56,$E$79,$E$102) -> 0.77718205 | ... O23: =(O37*$E$33 +O60*$E$56+O83*$E$79+O106*$E$102)/SUM($E$33,$E$56,$E$79,$E$102) -> 0.8495425 | P23: =SUMPRODUCT(D23:O23,$D$19:$O$19)/$P$19 -> 0.78366552 | R23: Ascott BP GOP | T23: =SUM(T40,T63,T86,T109) -> 78829987 | U23: =SUM(U40,U63,U86,U109) -> 71946283 | V23: =SUM(V40,V63,V86,V109) -> 54075826 | W23: =SUM(W40,W63,W86,W109) -> 56774030 | X23: =SUM(X40,X63,X86,X109) -> 49198564 | Y23: =SUM(Y40,Y63,Y86,Y109) -> 45330230 | Z23: =SUM(Z40,Z63,Z86,Z109) -> 64092156 | AA23: =SUM(AA40,AA63,AA86,AA109) -> 65576849 | ... AE23: =SUM(AE40,AE63,AE86,AE109) -> 82223512 | AF23: =SUM(T23:AE23) -> 7.5223514e+08
B24: Ascott BP ADR | D24: =(D38*$E$33*D37+$E$56*D60*D61+$E$79*D83*D84+$E$102*D106*D107)/SUM($E$33*D37,$E$56*D60,$E$79*D83,$E$102*D106) -> 3413.3662 | E24: =(E38*$E$33*E37+$E$56*E60*E61+$E$79*E83*E84+$E$102*E106*E107)/SUM($E$33*E37,$E$56*E60,$E$79*E83,$E$102*E106) -> 3382.6642 | F24: =(F38*$E$33*F37+$E$56*F60*F61+$E$79*F83*F84+$E$102*F106*F107)/SUM($E$33*F37,$E$56*F60,$E$79*F83,$E$102*F106) -> 3058.381 | G24: =(G38*$E$33*G37+$E$56*G60*G61+$E$79*G83*G84+$E$102*G106*G107)/SUM($E$33*G37,$E$56*G60,$E$79*G83,$E$102*G106) -> 3155.5803 | H24: =(H38*$E$33*H37+$E$56*H60*H61+$E$79*H83*H84+$E$102*H106*H107)/SUM($E$33*H37,$E$56*H60,$E$79*H83,$E$102*H106) -> 2873.2876 | I24: =(I38*$E$33*I37+$E$56*I60*I61+$E$79*I83*I84+$E$102*I106*I107)/SUM($E$33*I37,$E$56*I60,$E$79*I83,$E$102*I106) -> 2858.2878 | J24: =(J38*$E$33*J37+$E$56*J60*J61+$E$79*J83*J84+$E$102*J106*J107)/SUM($E$33*J37,$E$56*J60,$E$79*J83,$E$102*J106) -> 3100.3129 | K24: =(K38*$E$33*K37+$E$56*K60*K61+$E$79*K83*K84+$E$102*K106*K107)/SUM($E$33*K37,$E$56*K60,$E$79*K83,$E$102*K106) -> 3136.4953 | ... O24: =(O38*$E$33*O37+$E$56*O60*O61+$E$79*O83*O84+$E$102*O106*O107)/SUM($E$33*O37,$E$56*O60,$E$79*O83,$E$102*O106) -> 3435.8626 | P24: =SUMPRODUCT(D24:O24,$D$19:$O$19)/$P$19 -> 3147.9902 | R24: MF Projection GOP | T24: =SUM(T41,T64,T87,T110) -> 77659698 | U24: =SUM(U41,U64,U87,U110) -> 70852649 | V24: =SUM(V41,V64,V87,V110) -> 53059061 | W24: =SUM(W41,W64,W87,W110) -> 55017009 | X24: =SUM(X41,X64,X87,X110) -> 47617488 | Y24: =SUM(Y41,Y64,Y87,Y110) -> 43854493 | Z24: =SUM(Z41,Z64,Z87,Z110) -> 62331518 | AA24: =SUM(AA41,AA64,AA87,AA110) -> 63761097 | ... AE24: =SUM(AE41,AE64,AE87,AE110) -> 81065223 | AF24: =SUM(T24:AE24) -> 7.3571204e+08
B25: Ascott BP RevPar | D25: =D23*D24 -> 2848.0478 | E25: =E23*E24 -> 2945.1596 | F25: =F23*F24 -> 2197.3238 | G25: =G23*G24 -> 2368.552 | H25: =H23*H24 -> 2087.9821 | I25: =I23*I24 -> 2040.4484 | J25: =J23*J24 -> 2468.7079 | K25: =K23*K24 -> 2510.5865 | ... O25: =O23*O24 -> 2918.9112 | P25: =SUMPRODUCT(D25:O25,$D$19:$O$19)/$P$19 -> 2476.3448 | R25: GOP | T25: =SUM(T42,T65,T88,T111) -> 70392032 | U25: =SUM(U42,U65,U88,U111) -> 70154061 | V25: =SUM(V42,V65,V88,V111) -> 55119529 | W25: =SUM(W42,W65,W88,W111) -> 45624481 | X25: =SUM(X42,X65,X88,X111) -> 39377310 | Y25: =SUM(Y42,Y65,Y88,Y111) -> 37355440 | Z25: =SUM(Z42,Z65,Z88,Z111) -> 0 | AA25: =SUM(AA42,AA65,AA88,AA111) -> 0 | ... AE25: =SUM(AE42,AE65,AE88,AE111) -> 0 | AF25: =SUM(T25:AE25) -> 3.1802285e+08 | AH25: =AF42+AF65+AF88+AF111 -> 3.1802285e+08
B26: MF Projection OCC | D26: =(D41*$E$33 +D64*$E$56+D87*$E$79+D110*$E$102)/SUM($E$33,$E$56,$E$79,$E$102) -> 0.83245997 | E26: =(E41*$E$33+E64*$E$56+E87*$E$79+E110*$E$102)/SUM($E$33,$E$56,$E$79,$E$102) -> 0.86924574 | F26: =(F41*$E$33 +F64*$E$56+F87*$E$79+F110*$E$102)/SUM($E$33,$E$56,$E$79,$E$102) -> 0.71962682 | G26: =(G41*$E$33 +G64*$E$56+G87*$E$79+G110*$E$102)/SUM($E$33,$E$56,$E$79,$E$102) -> 0.74549583 | H26: =(H41*$E$33 +H64*$E$56+H87*$E$79+H110*$E$102)/SUM($E$33,$E$56,$E$79,$E$102) -> 0.72024562 | I26: =(I41*$E$33 +I64*$E$56+I87*$E$79+I110*$E$102)/SUM($E$33,$E$56,$E$79,$E$102) -> 0.70854197 | J26: =(J41*$E$33 +J64*$E$56+J87*$E$79+J110*$E$102)/SUM($E$33,$E$56,$E$79,$E$102) -> 0.78948881 | K26: =(K41*$E$33 +K64*$E$56+K87*$E$79+K110*$E$102)/SUM($E$33,$E$56,$E$79,$E$102) -> 0.79556986 | L26: =(L41*$E$33 +L64*$E$56+L87*$E$79+L110*$E$102)/SUM($E$33,$E$56,$E$79,$E$102) -> 0.71707167 | M26: =(M41*$E$33 +M64*$E$56+M87*$E$79+M110*$E$102)/SUM($E$33,$E$56,$E$79,$E$102) -> 0.77668535 | ... O26: =(O41*$E$33 +O64*$E$56+O87*$E$79+O110*$E$102)/SUM($E$33,$E$56,$E$79,$E$102) -> 0.85063067 | P26: =SUMPRODUCT(D26:O26,$D$19:$O$19)/$P$19 -> 0.78070581 | R26: Ascott BP EBIT | T26: =SUM(T46,,T69,T92,T115) -> 57537870 | U26: =SUM(U46,,U69,U92,U115) -> 51332229 | V26: =SUM(V46,,V69,V92,V115) -> 35073195 | W26: =SUM(W46,,W69,W92,W115) -> 37413950 | X26: =SUM(X46,,X69,X92,X115) -> 30716749 | Y26: =SUM(Y46,,Y69,Y92,Y115) -> 27129925 | Z26: =SUM(Z46,,Z69,Z92,Z115) -> 44385870 | AA26: =SUM(AA46,,AA69,AA92,AA115) -> 45590233 | ... AE26: =SUM(AE46,,AE69,AE92,AE115) -> 60670935 | AF26: =SUM(T26:AE26) -> 5.1508784e+08
B27: MF Projection ADR | D27: =(D42*$E$33*D41+$E$56*D64*D65+$E$79*D87*D88+$E$102*D110*D111)/SUM($E$33*D41,$E$56*D64,$E$79*D87,$E$102*D110) -> 3408.1318 | E27: =(E42*$E$33*E41+$E$56*E64*E65+$E$79*E87*E88+$E$102*E110*E111)/SUM($E$33*E41,$E$56*E64,$E$79*E87,$E$102*E110) -> 3377.196 | F27: =(F42*$E$33*F41+$E$56*F64*F65+$E$79*F87*F88+$E$102*F110*F111)/SUM($E$33*F41,$E$56*F64,$E$79*F87,$E$102*F110) -> 3056.3442 | G27: =(G42*$E$33*G41+$E$56*G64*G65+$E$79*G87*G88+$E$102*G110*G111)/SUM($E$33*G41,$E$56*G64,$E$79*G87,$E$102*G110) -> 3145.5632 | H27: =(H42*$E$33*H41+$E$56*H64*H65+$E$79*H87*H88+$E$102*H110*H111)/SUM($E$33*H41,$E$56*H64,$E$79*H87,$E$102*H110) -> 2862.1638 | I27: =(I42*$E$33*I41+$E$56*I64*I65+$E$79*I87*I88+$E$102*I110*I111)/SUM($E$33*I41,$E$56*I64,$E$79*I87,$E$102*I110) -> 2849.4452 | J27: =(J42*$E$33*J41+$E$56*J64*J65+$E$79*J87*J88+$E$102*J110*J111)/SUM($E$33*J41,$E$56*J64,$E$79*J87,$E$102*J110) -> 3089.5062 | K27: =(K42*$E$33*K41+$E$56*K64*K65+$E$79*K87*K88+$E$102*K110*K111)/SUM($E$33*K41,$E$56*K64,$E$79*K87,$E$102*K110) -> 3126.8681 | ... O27: =(O42*$E$33*O41+$E$56*O64*O65+$E$79*O87*O88+$E$102*O110*O111)/SUM($E$33*O41,$E$56*O64,$E$79*O87,$E$102*O110) -> 3433.0169 | P27: =SUMPRODUCT(D27:O27,$D$19:$O$19)/$P$19 -> 3141.2196 | R27: MF Projection EBIT | T27: =SUM(T47,T70,T93,T116) -> 44996152 | U27: =SUM(U47,U70,U93,U116) -> 38690161 | V27: =SUM(V47,V70,V93,V116) -> 22252719 | W27: =SUM(W47,W70,W93,W116) -> 24020516 | X27: =SUM(X47,,X70,X93,X116) -> 17224917 | Y27: =SUM(Y47,Y70,Y93,Y116) -> 13741714 | Z27: =SUM(Z47,,Z70,Z93,Z116) -> 30862861 | AA27: =SUM(AA47,,AA70,AA93,AA116) -> 32155929 | AB27: =SUM(AB47,,AB70,AB93,AB116) -> 16972068 | AC27: =SUM(AC47,,AC70,AC93,AC116) -> 29560676 | AD27: =SUM(AD47,,AD70,AD93,AD116) -> 39965937 | AE27: =SUM(AE47,,AE70,AE93,AE116) -> 48200653 | AF27: =SUM(T27:AE27) -> 3.586443e+08
B28: MF Projection RevPar | D28: =D26*D27 -> 2837.1333 | E28: =E26*E27 -> 2935.6132 | F28: =F26*F27 -> 2199.4272 | G28: =G26*G27 -> 2345.0042 | H28: =H26*H27 -> 2061.4609 | I28: =I26*I27 -> 2018.9515 | J28: =J26*J27 -> 2439.1306 | K28: =K26*K27 -> 2487.642 | ... O28: =O26*O27 -> 2920.2294 | P28: =SUMPRODUCT(D28:O28,$D$19:$O$19)/$P$19 -> 2462.1676 | R28: EBIT | T28: =SUM(T48,,T71,T94,T117) -> 39303688 | U28: =SUM(U48,,U71,U94,U117) -> 38665478 | V28: =SUM(V48,,V71,V94,V117) -> 25601072 | W28: =SUM(W48,W71,W94,W117) -> 17306245 | X28: =SUM(X48,X71,X94,X117) -> 10784995 | Y28: =SUM(Y48,Y71,Y94,Y117) -> 11586975 | Z28: =SUM(Z48,,Z71,Z94,Z117) -> 0 | AA28: =SUM(AA48,,AA71,AA94,AA117) -> 0 | AB28: =SUM(AB48,,AB71,AB94,AB117) -> 0 | AC28: =SUM(AC48,,AC71,AC94,AC117) -> 0 | AD28: =SUM(AD48,,AD71,AD94,AD117) -> 0 | AF28: =SUM(T28:AE28) -> 1.4324845e+08
B29: OCC | D29: =(D45*$E$33+D68*$E$56+D91*$E$79+D114*$E$102)/SUM($E$33,$E$56,$E$79,$E$102) -> 0.84680982 | E29: =(E45*$E$33+E68*$E$56+E91*$E$79+E114*$E$102)/SUM($E$33,$E$56,$E$79,$E$102) -> 0.90195666 | F29: =(F45*$E$33+F68*$E$56+F91*$E$79+F114*$E$102)/SUM($E$33,$E$56,$E$79,$E$102) -> 0.78072593 | G29: =(G45*$E$33+G68*$E$56+G91*$E$79+G114*$E$102)/SUM($E$33,$E$56,$E$79,$E$102) -> 0.67734413 | H29: =(H45*$E$33+H68*$E$56+H91*$E$79+H114*$E$102)/SUM($E$33,$E$56,$E$79,$E$102) -> 0.67288232 | I29: =(I45*$E$33+I68*$E$56+I91*$E$79+I114*$E$102)/SUM($E$33,$E$56,$E$79,$E$102) -> 0.67329406 | J29: =(J45*$E$33+J68*$E$56+J91*$E$79+J114*$E$102)/SUM($E$33,$E$56,$E$79,$E$102) -> 0 | K29: =(K45*$E$33+K68*$E$56+K91*$E$79+K114*$E$102)/SUM($E$33,$E$56,$E$79,$E$102) -> 0 | ... O29: =(O45*$E$33+O68*$E$56+O91*$E$79+O114*$E$102)/SUM($E$33,$E$56,$E$79,$E$102) -> 0 | P29: =(D29*31+E29*28+F29*31+G29*30+H29*31+I29*30+J29*31+K29*31+L29*30+M29*31+N29*30+O29*31)/365 -> 0.37558053 | R29: NPAT | T29: =SUM(T49,,T72,T95,T118) -> 11772077 | U29: =SUM(U49,,U72,U95,U118) -> 15370113 | V29: =SUM(V49,,V72,V95,V118) -> 1938903.3 | W29: =SUM(W49,W72,W95,W118) -> -3928433.6 | X29: =SUM(X49,,X72,X95,X118) -> -8451432.5 | Y29: =SUM(Y49,,Y72,Y95,Y118) -> -8768805.6 | Z29: =SUM(Z49,,Z72,Z95,Z118) -> 0 | AA29: =SUM(AA49,,AA72,AA95,AA118) -> 0 | AB29: =SUM(AB49,,AB72,AB95,AB118) -> 0 | AC29: =SUM(AC49,,AC72,AC95,AC118) -> 0 | AD29: =SUM(AD49,,AD72,AD95,AD118) -> 0 | AF29: =SUM(T29:AE29) -> 7932421.7
B30: ADR | D30: =(D48*$E$33*D45+D71*$E$56*D68+$E$79*D91*D94+$E$102*D114*D117)/SUM($E$33*D45,$E$56*D68,$E$79*D91,$E$102*D114) -> 3061.3411 | E30: =(E48*$E$33*E45+E71*$E$56*E68+$E$79*E91*E94+$E$102*E114*E117)/SUM($E$33*E45,$E$56*E68,$E$79*E91,$E$102*E114) -> 3145.9799 | F30: =(F48*$E$33*F45+F71*$E$56*F68+$E$79*F91*F94+$E$102*F114*F117)/SUM($E$33*F45,$E$56*F68,$E$79*F91,$E$102*F114) -> 2768.387 | G30: =(G48*$E$33*G45+G71*$E$56*G68+$E$79*G91*G94+$E$102*G114*G117)/SUM($E$33*G45,$E$56*G68,$E$79*G91,$E$102*G114) -> 2954.5516 | H30: =(H48*$E$33*H45+H71*$E$56*H68+$E$79*H91*H94+$E$102*H114*H117)/SUM($E$33*H45,$E$56*H68,$E$79*H91,$E$102*H114) -> 2603.8035 | I30: =(I48*$E$33*I45+I71*$E$56*I68+$E$79*I91*I94+$E$102*I114*I117)/SUM($E$33*I45,$E$56*I68,$E$79*I91,$E$102*I114) -> 2621.1105 | J30: =(J48*$E$33*J45+J71*$E$56*J68+$E$79*J91*J94+$E$102*J114*J117)/SUM($E$33*J45,$E$56*J68,$E$79*J91,$E$102*J114) -> #DIV/0! | K30: =(K48*$E$33*K45+K71*$E$56*K68+$E$79*K91*K94+$E$102*K114*K117)/SUM($E$33*K45,$E$56*K68,$E$79*K91,$E$102*K114) -> #DIV/0! | ... O30: =(O48*$E$33*O45+O71*$E$56*O68+$E$79*O91*O94+$E$102*O114*O117)/SUM($E$33*O45,$E$56*O68,$E$79*O91,$E$102*O114) -> #DIV/0! | P30: =(D30*31+E30*28+F30*31+G30*30+H30*31+I30*30+J30*31+K30*31+L30*30+M30*31+N30*30+O30*31)/365 -> #DIV/0!
B31: RevPar | D31: =D30*D29 -> 2592.3738 | E31: =E30*E29 -> 2837.5376 | F31: =F30*F29 -> 2161.3515 | G31: =G30*G29 -> 2001.2482 | H31: =H30*H29 -> 1752.0533 | I31: =I30*I29 -> 1764.7781 | J31: =J30*J29 -> #DIV/0! | K31: =K30*K29 -> #DIV/0! | ... O31: =O30*O29 -> #DIV/0! | P31: =P29*P30 -> #DIV/0!
E33: 445 | R33: kthb
B34: SR9 | D34: =$D$20 -> 2026 | P34: Avg | R34: SR9 | T34: =$T$20 -> 2026 | AF34: Total
D35: Jan | E35: Feb | F35: Mar | G35: Apr | H35: May | I35: Jun | J35: Jul | K35: Aug | L35: Sep | M35: Oct | N35: Nov | O35: Dec | T35: Jan | U35: Feb | V35: Mar | W35: Apr | X35: May | Y35: Jun | Z35: Jul | AA35: Aug | AB35: Sep | AC35: Oct | AD35: Nov | AE35: Dec
B36: Ascott BP | R36: Total Revenue | T36: 36981091 | U36: 36798669 | V36: 33026704 | W36: 31830716 | X36: 29125528 | Y36: 28515832 | AF36: =SUM(T36:AE36) -> 1.9627854e+08
B37: OCC | D37: 0.86682856 | E37: 0.89736758 | F37: 0.78208409 | G37: 0.7405618 | H37: 0.76889453 | I37: 0.75625468 | J37: 0.78172526 | K37: 0.78114534 | L37: 0.75531835 | M37: 0.82826386 | N37: 0.88472285 | O37: 0.88175788 | P37: =SUMPRODUCT(D37:O37,$D$19:$O$19)/$P$19 -> 0.80998276 | R37: Ascott BP OPEX | T37: -16102007 | U37: -15239925 | V37: -14991348 | W37: -14549704 | X37: -14823126 | Y37: -14725138 | Z37: -14489481 | AA37: -14909282 | AB37: -14592954 | AC37: -15669793 | AD37: -15866354 | AE37: -16319282 | AF37: =SUM(T37:AE37) -> -1.8227839e+08
B38: ADR | D38: 3317.7326 | E38: 3007.5041 | F38: 2910.1404 | G38: 2995.4479 | H38: 2715.1868 | I38: 2745.9736 | J38: 2818.788 | K38: 2826.5746 | L38: 2790.6075 | M38: 2866.9397 | N38: 2951.3856 | O38: 3008.2437 | P38: =SUMPRODUCT(D38:O38,$D$19:$O$19)/$P$19 -> 2912.5598 | R38: MF Projection OPEX | T38: -16395234 | U38: -15552638 | V38: -15311509 | W38: -14863558 | X38: -15140416 | Y38: -15055603 | Z38: -14831472 | AA38: -15230278 | AB38: -14920940 | AC38: -15984544 | AD38: -16174226 | AE38: -16620660 | AF38: =SUM(T38:AE38) -> -1.8608108e+08
B39: RevPar | D39: =D37*D38 -> 2875.9054 | E39: =E37*E38 -> 2698.8366 | F39: =F37*F38 -> 2275.9745 | G39: =G37*G38 -> 2218.3143 | H39: =H37*H38 -> 2087.6923 | I39: =I37*I38 -> 2076.6554 | J39: =J37*J38 -> 2203.5178 | K39: =K37*K38 -> 2207.9656 | ... O39: =O37*O38 -> 2652.5426 | P39: =SUMPRODUCT(D39:O39,$D$19:$O$19)/$P$19 -> 2364.4076 | R39: OPEX | T39: -14552035 | U39: -14296298 | V39: -14344313 | W39: -14055717 | X39: -13969285 | Y39: -13047220 | AF39: =SUM(T39:AE39) -> -84264867
B40: MF Projection | R40: Ascott BP GOP | T40: 28209612 | U40: 22596705 | V40: 20224083 | W40: 18115263 | X40: 17743371 | Y40: 16645896 | Z40: 20355990 | AA40: 19906821 | AB40: 17405107 | AC40: 21642539 | AD40: 23884688 | AE40: 25396436 | AF40: =SUM(T40:AE40) -> 2.5212651e+08
B41: OCC | D41: 0.86682856 | E41: 0.89736758 | F41: 0.78208409 | G41: 0.7405618 | H41: 0.76889453 | I41: 0.75625468 | J41: 0.78172526 | K41: 0.78114534 | L41: 0.75531835 | M41: 0.82826386 | N41: 0.88472285 | O41: 0.88175788 | P41: =SUMPRODUCT(D41:O41,$D$19:$O$19)/$P$19 -> 0.80998276 | R41: MF Projection GOP | T41: ='[275]YTD compare'!P10 -> 27916385 | U41: 22283993 | V41: 19903922 | W41: 17801409 | X41: 17426081 | Y41: 16315431 | Z41: 20014000 | AA41: 19585825 | AB41: 17077121 | AC41: 21327788 | AD41: 23576816 | AE41: 25095059 | AF41: =SUM(T41:AE41) -> 2.4832383e+08
B42: ADR | D42: 3317.7326 | E42: 3007.5041 | F42: 2910.1404 | G42: 2995.4479 | H42: 2715.1868 | I42: 2745.9736 | J42: 2818.788 | K42: 2826.5746 | L42: 2790.6075 | M42: 2866.9397 | N42: 2951.3856 | O42: 3008.2437 | P42: =SUMPRODUCT(D42:O42,$D$19:$O$19)/$P$19 -> 2912.5598 | R42: GOP | T42: =T36+T39 -> 22429057 | U42: =U36+U39 -> 22502371 | V42: =V36+V39 -> 18682391 | W42: =W36+W39 -> 17774999 | X42: =X36+X39 -> 15156242 | Y42: =Y36+Y39 -> 15468612 | AF42: =AF36+AF39 -> 1.1201367e+08
B43: RevPar | D43: =D41*D42 -> 2875.9054 | E43: =E41*E42 -> 2698.8366 | F43: =F41*F42 -> 2275.9745 | G43: =G41*G42 -> 2218.3143 | H43: =H41*H42 -> 2087.6923 | I43: =I41*I42 -> 2076.6554 | J43: =J41*J42 -> 2203.5178 | K43: =K41*K42 -> 2207.9656 | ... O43: =O41*O42 -> 2652.5426 | P43: =SUMPRODUCT(D43:O43,$D$19:$O$19)/$P$19 -> 2364.4076 | R43: Ascott BP % GOP | T43: 0.63661885 | U43: 0.5972177 | V43: 0.57429605 | W43: 0.55457772 | X43: 0.54483512 | Y43: 0.53061356 | Z43: 0.58417893 | AA43: 0.57177052 | AB43: 0.54394256 | AC43: 0.58003715 | AD43: 0.60085691 | AE43: 0.60879777 | AF43: =AVERAGE(T43:AE43) -> 0.5773119
B44: Actual Result | R44: MF Projection % GOP | T44: 0.63 | U44: 0.59 | V44: 0.57 | W44: 0.54 | X44: 0.54 | Y44: 0.52 | Z44: 0.57 | AA44: 0.56 | AB44: 0.53 | AC44: 0.57 | AD44: 0.59 | AE44: 0.6 | AF44: =AVERAGE(T44:AE44) -> 0.5675
